Workbook

Sheet Overview
C3: Data Input Spreadsheet Overview
C5: Purpose: This data input spreadsheet collects all the case study specific data that is
C6: fed into the optimization model. An advanced algorithm then considers this data along
C7: with any/all constraints specified to determine the best possible solution(s). Those
C8: solutions are then returned to the user as specific recommendations for action (e.g.
C9: haul 2,340 bbl of produced water from production pad A to completions pad B on
C10: Tuesday, March 23). See Figure 1 for a process illustration.
C12: Note 1: None of this data is stored in the model permanently. The model and the data
C13: are intentionally kept separated within the optimization framework.
C15: Note 2: Data is assumed to be deterministic initially. Eventually, users will be able
C16: to specify which inputs are uncertain, and the framework will aim to determine
C17: "robustified" recommendations that are near-optimal across a range of uncertainty
C18: realizations (i.e., "stochastic optimization").
C21: Data Input Tabs | F21: Description
C23: Production Pads | F23: List of all production pads to be considered
C24: Completion Pads | F24: List of all completion pads to be considered
C25: SWD Sites | F25: List of all disposal sites to be considered
C26: Drive Times | F26: Estimated drive times between locations
C27: Completions Demand | F27: Forecasted water demand at completions sites
C28: Flowback Rates | F28: Forecasted flowback rates (post-completions)
C29: Production Rates | F29: Forecated production rates (post-flowback)
C30: Disposal Capacity | F30: Forecasted disposal capacity
C31: External Water Costs | F31: Cost for sourcing external water for frac | M31: Figure 1: Illustration of the optimization workflow
C32: Reuse Costs | F32: Cost for FR/chemicals to reuse produced water
C33: Disposal Costs | F33: Cost for disposing produced water
C34: Hauling Rates | F34: Cost for hauling produced water via trucks
C35: Transfer Lines | F35: List of all existing water transfer lines
C36: Pipeline Expansion | F36: Cost for installing new transfer lines

Sheet Schematic

Sheet Units
A1: Units
A2: INDEX | B2: VALUE | D2: Unit Description | E2: Unit Relationships
A3: volume | B3: bbl | D3: Volume units are used to represent water flows (e.g. bbl/day), flow capacities, storage capacity, costs etc. | E3: bbl | F3: = | G3: 42 gallons | I3: kbbl | J3: = | K3: 1000 bbl
A4: distance | B4: mile | D4: Distance units are used for defining lengths of pipelines and pipeline expansion costs | E4: kmeter | F4: = | G4: 1000 m
A5: diameter | B5: inch | D5: This unit applies to diameter of pipelines and pipeline expansion costs
A6: concentration | B6: mg/liter | D6: Concentration unit defines water quality (e.g., TDS concentration) | E6: mg/liter | F6: = | G6: ppm
A7: currency | B7: USD | D7: Currency unit defines costs | E7: kUSD | F7: = | G7: 1000 USD
A8: time | B8: day | D8: Time units refers to input data relative to time (e.g., water flows in bbl/day) | AT8: volume | AU8: distance | AV8: diameter | AW8: concentration | AX8: currency | AY8: time | AZ8: pressure | BA8: decision_period
A9: pressure | B9: psi | D9: Pressure units when using the hydraulics module | E9: psi | F9: = | G9: 6895 Pa | AT9: bbl | AU9: foot | AV9: inch | AW9: mg/liter | AX9: USD | AY9: day | AZ9: pascal | BA9: day
A10: elevation | B10: foot | D10: Elevation of a network node (including all sites) | AT10: kbbl | AU10: mile | AV10: cm | AW10: kg/liter | AX10: kUSD | AY10: week | AZ10: psi | BA10: week
A11: decision period | B11: week | D11: The decision period is the amount of time in a single decision period or discretization (e.g., T01 is 1 week) | E11: fortnight | F11: = | G11: 2 weeks | I11: month | J11: = | K11: 30.44 days | AU11: meter | BA11: fortnight
A12: mass | B12: g | D12: Mass units is used for measuring emissions coefficients (e.g. 10g per treated produced water bbl). | E12: kg | F12: = | G12: 1000g | AU12: kmeter | BB12: month

Sheet ProductionPads
A1: List of all Production Pad Identifiers [-]
A2: PP01
A3: PP02
A4: PP03
A5: PP04
A6: PP05
A7: PP06
A8: PP07
A9: PP08
A10: PP09
A11: PP10
A12: PP11
... A15: PP14

Sheet ProductionTanks
A1: List of all Production Tank Identifiers [-]
A2: A01
A3: A02
A4: A03
A5: A04
A6: A05
A7: A06
A8: A07
A9: A08
A10: A09
A11: A10
A12: A11
... A15: A14

Sheet CompletionsPads
A1: List of all Completion Pad Identifiers [-]
A2: CP01
A3: CP02
A4: CP03

Sheet SWDSites
A1: List of all SWD Sites [-]
A2: K01
A3: K02
A4: K03
A5: K04
A6: K05

Sheet ExternalWaterSources
A1: List of all External Water Source Identifiers [-]
A2: F01
A3: F02

Sheet WaterQualityComponents
A1: List of all Water Quality Components [-]
A2: TDS

Sheet AirEmissionsComponents
A1: List of all Air Emissions Components [-]
A2: CO2
A3: NH3
A4: NOx
A5: SO2
A6: PM 2.5

Sheet StorageSites
A1: List of all Storage Site Identifiers [-] | Note: These correspond with Clean Brine Treatment Facilities
A2: S02
A3: S04
A4: S05

Sheet TreatmentSites
A1: List of all Treatment Site Identifiers [-]
A2: R02
A3: R03
A4: R04
A5: R05

Sheet TreatmentTechnologies
A1: List of all Treatment Site Identifiers [-]
A2: CB
A3: CB-EV
A4: MVC
A5: MD
A6: OARO

Sheet ReuseOptions
A1: List of all Reuse Option Identifiers [-]

Sheet NetworkNodes
A1: List of all Network Node Identifiers [-]
A2: N01
A3: N02
A4: N03
A5: N04
A6: N05
A7: N06
A8: N07
A9: N08
A10: N09
A11: N10
A12: N11
... A29: N28

Sheet PipelineDiameters
A1: List of all Pipeline Diameter Identifiers [-]
A2: D0
A3: D4
A4: D8

Sheet StorageCapacities
A1: List of all Storage Capacity Identifiers [-]
A2: C0
A3: C1

Sheet TreatmentCapacities
A1: List of all Treatment Capacity Identifiers [-]
A2: J0
A3: J1
A4: J2
A5: J3

Sheet InjectionCapacities
A1: List of all Injection Capacity Identifiers [-]
A2: I0
A3: I1

Sheet PNA
A1: Production Pads to Network Nodes Piping Arcs [-]
A2: ProductionPads | B2: N01 | C2: N02 | D2: N03 | E2: N04 | F2: N05 | G2: N06 | H2: N07 | I2: N08 | J2: N09 | K2: N10 | L2: N11 | M2: N12 | N2: N13 | O2: N14 | P2: N15 | Q2: N16 | R2: N17 | S2: N18 | T2: N19 | U2: N20 | V2: N21 | W2: N22 | X2: N23 | Y2: N24 | Z2: N25 | AA2: N26 | AB2: N27 | AC2: N28
A3: PP01 | B3: 1
A4: PP02 | F4: 1
A5: PP03 | G5: 1
A6: PP04 | L6: 1
A7: PP05 | K7: 1 | M7: 1
A8: PP06 | Q8: 1
A9: PP07 | P9: 1
A10: PP08 | S10: 1
A11: PP09 | V11: 1
A12: PP10 | T12: 1
A13: PP11 | Z13: 1
A14: PP12 | AB14: 1
A15: PP13 | AB15: 1
A16: PP14 | AB16: 1

Sheet CNA
A1: Completions Pads to Network Nodes Piping Arcs [-]
A2: CompletionsPads | B2: N01 | C2: N02 | D2: N03 | E2: N04 | F2: N05 | G2: N06 | H2: N07 | I2: N08 | J2: N09 | K2: N10 | L2: N11 | M2: N12 | N2: N13 | O2: N14 | P2: N15 | Q2: N16 | R2: N17 | S2: N18 | T2: N19 | U2: N20 | V2: N21 | W2: N22 | X2: N23 | Y2: N24 | Z2: N25 | AA2: N26 | AB2: N27 | AC2: N28
A3: CP01 | I3: 1
A4: CP02 | R4: 1
A5: CP03

Sheet CCA
A1: Completions Pads to Completions Pads Piping Arcs [-]
A2: CompletionsPads | B2: CP01 | C2: CP02 | D2: CP03
A3: CP01
A4: CP02
A5: CP03

Sheet NNA
A1: Network Nodes to Network Nodes Piping Arcs [-]
A2: NetworkNodes | B2: N01 | C2: N02 | D2: N03 | E2: N04 | F2: N05 | G2: N06 | H2: N07 | I2: N08 | J2: N09 | K2: N10 | L2: N11 | M2: N12 | N2: N13 | O2: N14 | P2: N15 | Q2: N16 | R2: N17 | S2: N18 | T2: N19 | U2: N20 | V2: N21 | W2: N22 | X2: N23 | Y2: N24 | Z2: N25 | AA2: N26 | AB2: N27 | AC2: N28
A3: N01 | C3: 1
A4: N02 | B4: 1 | D4: 1 | F4: 1
A5: N03 | C5: 1 | E5: 1
A6: N04 | D6: 1 | G6: 1
A7: N05 | C7: 1 | I7: 1
A8: N06 | E8: 1 | H8: 1
A9: N07 | G9: 1 | I9: 1 | J9: 1
A10: N08 | F10: 1 | H10: 1
A11: N09 | H11: 1 | K11: 1 | L11: 1
A12: N10 | J12: 1
A13: N11 | J13: 1 | N13: 1
A14: N12 | O14: 1
A15: N13 | L15: 1 | O15: 1
A16: N14 | M16: 1 | N16: 1 | AC16: 1
A17: N15 | Q17: 1 | AC17: 1
A18: N16 | P18: 1 | R18: 1
A19: N17 | Q19: 1
A20: N18 | T20: 1
A21: N19 | S21: 1 | W21: 1
A22: N20 | V22: 1 | AC22: 1
A23: N21 | U23: 1 | W23: 1
A24: N22 | T24: 1 | V24: 1 | X24: 1
A25: N23 | W25: 1 | Y25: 1
A26: N24 | X26: 1 | Z26: 1
A27: N25 | Y27: 1 | AA27: 1
A28: N26 | Z28: 1 | AB28: 1
A29: N27 | AA29: 1
A30: N28 | O30: 1 | P30: 1 | U30: 1

Sheet NCA
A1: Network Nodes to Completions Pads Piping Arcs [-]
A2: NetworkNodes | B2: CP01 | C2: CP02 | D2: CP03
A3: N01
A4: N02
A5: N03
A6: N04
A7: N05
A8: N06
A9: N07
A10: N08
A11: N09
A12: N10
A13: N11
A14: N12
... A30: N28

Sheet NKA
A1: Network Nodes to Disposal Sites Piping Arcs [-]
A2: NetworkNodes | B2: K01 | C2: K02 | D2: K03 | E2: K04 | F2: K05
A3: N01 | B3: 1
A4: N02
A5: N03
A6: N04 | C6: 1
A7: N05
A8: N06
A9: N07
A10: N08
A11: N09
A12: N10
A13: N11
A14: N12
A15: N13 | D15: 1
A16: N14
A17: N15
A18: N16
A19: N17 | E19: 1
A20: N18 | E20: 1
A21: N19
A22: N20
A23: N21
A24: N22 | D24: 1
A25: N23
A26: N24
A27: N25
A28: N26 | F28: 1
A29: N27
A30: N28

Sheet NRA
A1: Network Nodes to Treatment Sites Piping Arcs [-]
A2: NetworkNodes | B2: R02 | C2: R03 | D2: R04 | E2: R05
A3: N01
A4: N02
A5: N03
A6: N04
A7: N05
A8: N06
A9: N07
A10: N08
A11: N09
A12: N10 | B12: 1
A13: N11
A14: N12 | C14: 1
A15: N13
A16: N14
A17: N15
A18: N16
A19: N17
A20: N18
A21: N19
A22: N20 | D22: 1
A23: N21
A24: N22
A25: N23 | E25: 1
A26: N24
A27: N25
A28: N26
A29: N27
A30: N28

Sheet NSA
A1: Network Nodes to Storage Sites Piping Arcs [-]
A2: NetworkNodes | B2: S02 | C2: S04 | D2: S05
A3: N12

Sheet NOA
A1: Network Nodes to Beneficial Reuse Piping Arcs [-]

Sheet SNA
A1: Storage Sites to Network Nodes Piping Arcs [-]
A2: StorageSites | B2: N12
A3: S02
A4: S04
A5: S05

Sheet SOA
A1: Storage Sites to Beneficial Reuse Piping Arcs [-]

Sheet FCA
A1: External Water Sources to Completions Pads Piping Arcs [-]
A2: ExternalWaterSources | B2: CP01 | C2: CP02
A3: F01 | B3: 1 | C3: 1
A4: F02 | B4: 1 | C4: 1

Sheet RCA
A1: Treatment Sites to Completions Sites Piping Arcs (1 denotes an arc for the treated stream and 2 denotes an arc for the residual stream) [-]
A2: TreatmentSites | B2: CP01 | C2: CP02 | D2: CP03
A3: R02
A4: R03
A5: R04
A6: R05

Sheet RSA
A1: Treatment Sites to Storage Sites Piping Arcs (1 denotes an arc for the treated stream and 2 denotes an arc for the residual stream) [-]
A2: TreatmentSites | B2: S02 | C2: S04 | D2: S05
A3: R02 | B3: 1
A4: R03
A5: R04 | C5: 1
A6: R05 | D6: 1

Sheet SCA
A1: Storage Sites to Completions Piping Arcs [-]
A2: StorageSites | B2: CP01 | C2: CP02 | D2: CP03
A3: S02 | B3: 1
A4: S04 | C4: 1
A5: S05 | D5: 1

Sheet RNA
A1: Treatment Sites to Network Nodes Piping Arcs (1 denotes an arc for the treated stream and 2 denotes an arc for the residual stream) [-]
A2: TreatmentSites | B2: N03 | C2: N10 | D2: N12 | E2: N20 | F2: N23 | G2: N24
A3: R02
A4: R03
A5: R04
A6: R05

Sheet ROA
A1: Treatment Sites to Beneficial Reuse Piping Arcs (1 denotes an arc for the treated stream and 2 denotes an arc for the residual stream) [-]

Sheet RKA
A1: Treatment Sites to Disposal Piping Arcs (1 denotes an arc for the treated stream and 2 denotes an arc for the residual stream) [-]

Sheet PCT
A1: Production Pads to Completions Pads Trucking Arcs [-]
A2: ProductionPads | B2: CP01 | C2: CP02 | D2: CP03
A3: PP01
A4: PP02
A5: PP03
A6: PP04
A7: PP05
A8: PP06
A9: PP07
A10: PP08
A11: PP09
A12: PP10
A13: PP11
A14: PP12
... A16: PP14

Sheet FCT
A1: External Water Sources to Completions Pads Trucking Arcs [-]
A2: ExternalWaterSources | B2: CP01 | C2: CP02
A3: F01 | B3: 1 | C3: 1
A4: F02 | B4: 1 | C4: 1

Sheet PKT
A1: Production Pads to Disposal Sites Trucking Arcs [-]
A2: ProductionPads | B2: K01 | C2: K02 | D2: K03 | E2: K04 | F2: K05
A3: PP01 | B3: 1 | C3: 1 | D3: 1 | E3: 1 | F3: 1
A4: PP02 | B4: 1 | C4: 1 | D4: 1 | E4: 1 | F4: 1
A5: PP03 | B5: 1 | C5: 1 | D5: 1 | E5: 1 | F5: 1
A6: PP04 | B6: 1 | C6: 1 | D6: 1 | E6: 1 | F6: 1
A7: PP05 | B7: 1 | C7: 1 | D7: 1 | E7: 1 | F7: 1
A8: PP06 | B8: 1 | C8: 1 | D8: 1 | E8: 1 | F8: 1
A9: PP07 | B9: 1 | C9: 1 | D9: 1 | E9: 1 | F9: 1
A10: PP08 | B10: 1 | C10: 1 | D10: 1 | E10: 1 | F10: 1
A11: PP09 | B11: 1 | C11: 1 | D11: 1 | E11: 1 | F11: 1
A12: PP10 | B12: 1 | C12: 1 | D12: 1 | E12: 1 | F12: 1
A13: PP11 | B13: 1 | C13: 1 | D13: 1 | E13: 1 | F13: 1
A14: PP12 | B14: 1 | C14: 1 | D14: 1 | E14: 1 | F14: 1
... A16: PP14 | B16: 1 | C16: 1 | D16: 1 | E16: 1 | F16: 1

Sheet CKT
A1: Completions Pads to Disposal Sites Trucking Arcs [-]
A2: CompletionsPads | B2: K01 | C2: K02 | D2: K03 | E2: K04 | F2: K05
A3: CP01 | B3: 1 | C3: 1 | D3: 1 | E3: 1 | F3: 1
A4: CP02 | B4: 1 | C4: 1 | D4: 1 | E4: 1 | F4: 1
A5: CP03 | B5: 1 | C5: 1 | D5: 1 | E5: 1 | F5: 1

Sheet CCT
A1: Completions Pads to Completions Pads Trucking Arcs [-]
A2: CompletionsPads | B2: CP01 | C2: CP02 | D2: CP03
A3: CP01
A4: CP02
A5: CP03

Sheet CST
A1: Completions Pads to Storage Sites Trucking Arcs [-]
A2: CompletionsPads | B2: S02
A3: CP01

Sheet RST
A1: Treatment Sites to Storage Sites Trucking Arcs (1 denotes an arc for the treated stream and 2 denotes an arc for the residual stream) [-]
A2: TreatmentSites | B2: S02 | C2: S04 | D2: S05
A3: R02
A4: R03
A5: R04
A6: R05

Sheet ROT
A1: Treatment Sites to Beneficial Reuse Trucking Arcs (1 denotes an arc for the treated stream and 2 denotes an arc for the residual stream) [-]

Sheet SOT
A1: Storage Sites to Beneficial Reuse Trucking Arcs [-]

Sheet RKT
A1: Treatment Sites to Disposal Trucking Arcs (1 denotes an arc for the treated stream and 2 denotes an arc for the residual stream) [-]

Sheet Elevation
A1: Elevation Data in ft
A2: NODES | B2: VALUE
A3: PP01 | B3: 650
A4: PP02 | B4: 550
A5: PP03 | B5: 550
A6: PP04 | B6: 450
A7: PP05 | B7: 450
A8: PP06 | B8: 300
A9: PP07 | B9: 250
A10: PP08 | B10: 250
A11: PP09 | B11: 250
A12: PP10 | B12: 200
A13: PP11 | B13: 250
A14: PP12 | B14: 200
... A61: N28 | B61: 150

Sheet CompletionsDemand
A1: =_xlfn.CONCAT( "Table of Completions Water Demand for Completions Sites over ",VLOOKUP("decision period", Units!$A$2:$B$11, 2, FALSE),"s [",VLOOKUP("volume", Units!$A$2:$B$11, 2, FALSE),"/", VLOOKUP("time", Units!$A$2:$B$11, 2, FALSE),"]") -> Table of Completions Water Demand for Completions Sites over weeks [bbl/day]
A2: CompletionsPads | B2: T01 | C2: T02 | D2: T03 | E2: T04 | F2: T05 | G2: T06 | H2: T07 | I2: T08 | J2: T09 | K2: T10 | L2: T11 | M2: T12 | N2: T13 | O2: T14 | P2: T15 | Q2: T16 | R2: T17 | S2: T18 | T2: T19 | U2: T20 | V2: T21 | W2: T22 | X2: T23 | Y2: T24 | Z2: T25 | AA2: T26 | AB2: T27 | AC2: T28 | AD2: T29 | AE2: T30 | AF2: T31 | AG2: T32 | AH2: T33 | AI2: T34 | AJ2: T35 | AK2: T36 | AL2: T37 | AM2: T38 | AN2: T39 | AO2: T40 | AP2: T41 | AQ2: T42 | AR2: T43 | AS2: T44 | AT2: T45 | AU2: T46 | AV2: T47 | AW2: T48 | AX2: T49 | AY2: T50 | AZ2: T51 | BA2: T52
A3: CP01 | B3: 0 | C3: 45000 | D3: 50000 | E3: 50000 | F3: 50000 | G3: 50000 | H3: 50000 | I3: 50000 | J3: 50000 | K3: 50000 | L3: 37142.857 | M3: 0 | N3: 0 | O3: 0 | P3: 0 | Q3: 0 | R3: 0 | S3: 0 | T3: 0 | U3: 0 | V3: 0 | W3: 0 | X3: 0 | Y3: 0 | Z3: 0 | AA3: 0 | AB3: 0 | AC3: 0 | AD3: 0 | AE3: 0 | AF3: 0 | AG3: 0 | AH3: 0 | AI3: 0 | AJ3: 0 | AK3: 0 | AL3: 0 | AM3: 0 | AN3: 0 | AO3: 0 | AP3: 0 | AQ3: 0 | AR3: 0 | AS3: 0 | AT3: 10714.286 | AU3: 45714.286 | AV3: 45714.286 | AW3: 45714.286 | AX3: 45714.286 | AY3: 45714.286 | AZ3: 22857.143 | BA3: 11428.571
A4: CP02 | B4: 0 | C4: 0 | D4: 0 | E4: 0 | F4: 0 | G4: 0 | H4: 0 | I4: 0 | J4: 0 | K4: 0 | L4: 0 | M4: 0 | N4: 0 | O4: 0 | P4: 0 | Q4: 0 | R4: 0 | S4: 0 | T4: 0 | U4: 0 | V4: 0 | W4: 40000 | X4: 42857.143 | Y4: 42857.143 | Z4: 42857.143 | AA4: 42857.143 | AB4: 42857.143 | AC4: 42857.143 | AD4: 42857.143 | AE4: 42857.143 | AF4: 42857.143 | AG4: 42857.143 | AH4: 42857.143 | AI4: 42857.143 | AJ4: 21428.571 | AK4: 0 | AL4: 0 | AM4: 0 | AN4: 0 | AO4: 0 | AP4: 0 | AQ4: 0 | AR4: 0 | AS4: 0 | AT4: 0 | AU4: 0 | AV4: 0 | AW4: 0 | AX4: 0 | AY4: 0 | AZ4: 0 | BA4: 0
A5: CP03 | B5: 0 | C5: 0 | D5: 0 | E5: 0 | F5: 0 | G5: 0 | H5: 0 | I5: 0 | J5: 0 | K5: 0 | L5: 0 | M5: 0 | V5: 0 | W5: 0 | X5: 0 | Y5: 0 | Z5: 0 | AA5: 0 | AB5: 0 | AC5: 0 | AD5: 0 | AE5: 0 | AF5: 0 | AG5: 0 | AH5: 0 | AI5: 0 | AJ5: 0 | AK5: 0 | AL5: 0 | AM5: 0 | AN5: 0 | AO5: 0 | AP5: 0 | AQ5: 0 | AR5: 20000 | AS5: 20000 | AT5: 20000 | AU5: 20000 | AV5: 20000 | AW5: 20000 | AX5: 20000 | AY5: 10000 | AZ5: 0 | BA5: 0

Sheet PadRates
A1: =_xlfn.CONCAT( "Table of Production Rate Forecasts by Pads [",VLOOKUP("volume", Units!$A$2:$B$11, 2, FALSE),"/", VLOOKUP("time", Units!$A$2:$B$11, 2, FALSE),"]") -> Table of Production Rate Forecasts by Pads [bbl/day]
A2: ProductionPads | B2: T01 | C2: T02 | D2: T03 | E2: T04 | F2: T05 | G2: T06 | H2: T07 | I2: T08 | J2: T09 | K2: T10 | L2: T11 | M2: T12 | N2: T13 | O2: T14 | P2: T15 | Q2: T16 | R2: T17 | S2: T18 | T2: T19 | U2: T20 | V2: T21 | W2: T22 | X2: T23 | Y2: T24 | Z2: T25 | AA2: T26 | AB2: T27 | AC2: T28 | AD2: T29 | AE2: T30 | AF2: T31 | AG2: T32 | AH2: T33 | AI2: T34 | AJ2: T35 | AK2: T36 | AL2: T37 | AM2: T38 | AN2: T39 | AO2: T40 | AP2: T41 | AQ2: T42 | AR2: T43 | AS2: T44 | AT2: T45 | AU2: T46 | AV2: T47 | AW2: T48 | AX2: T49 | AY2: T50 | AZ2: T51 | BA2: T52
A3: PP01 | B3: 5000 | C3: 4322.6862 | D3: 3969.8541 | E3: 3737.1231 | F3: 3566.0408 | G3: 3432.0866 | H3: 3322.7634 | I3: 3230.8821 | J3: 3151.9482 | K3: 3082.975 | L3: 3021.8823 | M3: 2967.1667 | N3: 2917.7085 | O3: 2872.6527 | P3: 2831.3323 | Q3: 2793.2178 | R3: 2757.8823 | S3: 2724.9766 | T3: 2694.2119 | U3: 2665.3467 | V3: 2638.1771 | W3: 2612.5297 | X3: 2588.2556 | Y3: 2565.2261 | Z3: 2543.3293 | AA3: 2522.4676 | AB3: 2502.5549 | AC3: 2483.5152 | AD3: 2465.281 | AE3: 2447.7922 | AF3: 2430.9949 | AG3: 2414.8408 | AH3: 2399.2863 | AI3: 2384.2919 | AJ3: 2369.8219 | AK3: 2355.8437 | AL3: 2342.3276 | AM3: 2329.2465 | AN3: 2316.5754 | AO3: 2304.2914 | AP3: 2292.3736 | AQ3: 2280.8024 | AR3: 2269.5598 | AS3: 2258.6292 | AT3: 2247.9952 | AU3: 2237.6433 | AV3: 2227.5602 | AW3: 2217.7334 | AX3: 2208.1513 | AY3: 2198.8029 | AZ3: 2189.6781 | BA3: 2180.7672
A4: PP02 | B4: 13000 | C4: 10199.593 | D4: 8850.1557 | E4: 8002.4387 | F4: 7401.2292 | G4: 6943.6915 | H4: 6578.9872 | I4: 6278.5861 | J4: 6025.0197 | K4: 5806.8867 | L4: 5616.3726 | M4: 5447.9099 | N4: 5297.405 | O4: 5161.7687 | P4: 5038.6177 | Q4: 4926.0788 | R4: 4822.6554 | S4: 4727.1347 | T4: 4638.5217 | U4: 4555.991 | V4: 4478.8508 | W4: 4406.5166 | X4: 4338.4901 | Y4: 4274.3435 | Z4: 4213.7072 | AA4: 4156.2597 | AB4: 4101.7202 | AC4: 4049.8416 | AD4: 4000.4058 | AE4: 3953.2194 | AF4: 3908.1098 | AG4: 3864.9231 | AH4: 3823.5209 | AI4: 3783.7787 | AJ4: 3745.584 | AK4: 3708.8347 | AL4: 3673.4383 | AM4: 3639.3104 | AN4: 3606.3738 | AO4: 3574.5581 | AP4: 3543.7984 | AQ4: 3514.0351 | AR4: 3485.2135 | AS4: 3457.2829 | AT4: 3430.1963 | AU4: 3403.9103 | AV4: 3378.3847 | AW4: 3353.5819 | AX4: 3329.4671 | AY4: 3306.0076 | AZ4: 3283.1732 | BA4: 3260.9353
A5: PP03 | B5: 8000 | C5: 6727.1713 | D5: 6078.6855 | E5: 5656.8542 | F5: 5349.9224 | G5: 5111.5448 | H5: 4918.3052 | I5: 4756.8285 | J5: 4618.8022 | K5: 4498.7306 | L5: 4392.8039 | M5: 4298.2797 | N5: 4213.1231 | O5: 4135.7852 | P5: 4065.062 | Q5: 4000 | R5: 3939.8325 | S5: 3883.9342 | T5: 3831.789 | U5: 3782.9664 | V5: 3737.1038 | W5: 3693.893 | X5: 3653.0703 | Y5: 3614.408 | Z5: 3577.7088 | AA5: 3542.8001 | AB5: 3509.5307 | AC5: 3477.767 | AD5: 3447.3906 | AE5: 3418.2961 | AF5: 3390.3893 | AG5: 3363.5857 | AH5: 3337.8092 | AI5: 3312.991 | AJ5: 3289.0689 | AK5: 3265.9863 | AL5: 3243.6916 | AM5: 3222.1376 | AN5: 3201.2813 | AO5: 3181.0829 | AP5: 3161.5061 | AQ5: 3142.5172 | AR5: 3124.0852 | AS5: 3106.1814 | AT5: 3088.7792 | AU5: 3071.8537 | AV5: 3055.382 | AW5: 3039.3427 | AX5: 3023.7158 | AY5: 3008.4825 | AZ5: 2993.6253 | BA5: 2979.1279
A6: PP04 | B6: 2000 | C6: 1972.4654 | D6: 1956.5348 | E6: 1945.3099 | F6: 1936.6476 | G6: 1929.5986 | H6: 1923.6588 | I6: 1918.5282 | J6: 1914.0142 | K6: 1909.9852 | L6: 1906.3478 | M6: 1903.0332 | N6: 1899.9892 | O6: 1897.1752 | P6: 1894.5592 | Q6: 1892.1153 | R6: 1889.8225 | S6: 1887.6634 | T6: 1885.6232 | U6: 1883.6898 | V6: 1881.8526 | W6: 1880.1026 | X6: 1878.4318 | Y6: 1876.8336 | Z6: 1875.3019 | AA6: 1873.8315 | AB6: 1872.4176 | AC6: 1871.0562 | AD6: 1869.7435 | AE6: 1868.4762 | AF6: 1867.2513 | AG6: 1866.066 | AH6: 1864.9179 | AI6: 1863.8048 | AJ6: 1862.7245 | AK6: 1861.6753 | AL6: 1860.6555 | AM6: 1859.6633 | AN6: 1858.6975 | AO6: 1857.7565 | AP6: 1856.8393 | AQ6: 1855.9446 | AR6: 1855.0714 | AS6: 1854.2186 | AT6: 1853.3854 | AU6: 1852.5709 | AV6: 1851.7742 | AW6: 1850.9947 | AX6: 1850.2315 | AY6: 1849.4841 | AZ6: 1848.7517 | BA6: 1848.0339
A7: PP05 | B7: 1500 | C7: 1489.6387 | D7: 1483.611 | E7: 1479.3491 | F7: 1476.0517 | G7: 1473.363 | H7: 1471.0935 | I7: 1469.1304 | J7: 1467.4011 | K7: 1465.8558 | L7: 1464.4594 | M7: 1463.1857 | N7: 1462.015 | O7: 1460.9319 | P7: 1459.9243 | Q7: 1458.9824 | R7: 1458.0982 | S7: 1457.265 | T7: 1456.4773 | U7: 1455.7304 | V7: 1455.0203 | W7: 1454.3436 | X7: 1453.6973 | Y7: 1453.0787 | Z7: 1452.4857 | AA7: 1451.9161 | AB7: 1451.3683 | AC7: 1450.8405 | AD7: 1450.3315 | AE7: 1449.8399 | AF7: 1449.3646 | AG7: 1448.9045 | AH7: 1448.4587 | AI7: 1448.0264 | AJ7: 1447.6067 | AK7: 1447.1989 | AL7: 1446.8025 | AM7: 1446.4167 | AN7: 1446.041 | AO7: 1445.675 | AP7: 1445.318 | AQ7: 1444.9698 | AR7: 1444.6298 | AS7: 1444.2977 | AT7: 1443.9732 | AU7: 1443.6559 | AV7: 1443.3454 | AW7: 1443.0416 | AX7: 1442.7441 | AY7: 1442.4526 | AZ7: 1442.167 | BA7: 1441.887
A8: PP06 | B8: 7000 | C8: 6221.8988 | D8: 5807.476 | E8: 5530.2892 | F8: 5324.4302 | G8: 5161.9326 | H8: 5028.418 | I8: 4915.5571 | J8: 4818.1111 | K8: 4732.5808 | L8: 4656.518 | M8: 4588.146 | N8: 4526.1367 | O8: 4469.4725 | P8: 4417.3573 | Q8: 4369.1569 | R8: 4324.3588 | S8: 4282.5428 | T8: 4243.3605 | U8: 4206.5198 | V8: 4171.7739 | W8: 4138.9119 | X8: 4107.7529 | Y8: 4078.14 | Z8: 4049.9367 | AA8: 4023.0235 | AB8: 3997.295 | AC8: 3972.658 | AD8: 3949.0295 | AE8: 3926.3357 | AF8: 3904.5101 | AG8: 3883.4932 | AH8: 3863.2309 | AI8: 3843.6747 | AJ8: 3824.7801 | AK8: 3806.5068 | AL8: 3788.818 | AM8: 3771.6799 | AN8: 3755.0615 | AO8: 3738.9344 | AP8: 3723.2722 | AQ8: 3708.0507 | AR8: 3693.2474 | AS8: 3678.8416 | AT8: 3664.8138 | AU8: 3651.1461 | AV8: 3637.8217 | AW8: 3624.8249 | AX8: 3612.1411 | AY8: 3599.7566 | AZ8: 3587.6586 | BA8: 3575.835
A9: PP07 | B9: 10000 | C9: 8122.524 | D9: 7192.2309 | E9: 6597.5396 | F9: 6170.3386 | G9: 5841.9068 | H9: 5577.8983 | I9: 5358.8673 | J9: 5172.8186 | K9: 5011.8723 | L9: 4870.597 | M9: 4745.1028 | N9: 4632.5167 | O9: 4530.6612 | P9: 4437.85 | Q9: 4352.7528 | R9: 4274.3032 | S9: 4201.6343 | T9: 4134.0328 | U9: 4070.9053 | V9: 4011.7532 | W9: 3956.1541 | X9: 3903.7469 | Y9: 3854.2211 | Z9: 3807.3079 | AA9: 3762.7728 | AB9: 3720.4106 | AC9: 3680.0404 | AD9: 3641.5024 | AE9: 3604.6543 | AF9: 3569.3694 | AG9: 3535.5339 | AH9: 3503.0458 | AI9: 3471.813 | AJ9: 3441.7521 | AK9: 3412.7875 | AL9: 3384.8504 | AM9: 3357.8781 | AN9: 3331.813 | AO9: 3306.6026 | AP9: 3282.1985 | AQ9: 3258.5562 | AR9: 3235.6345 | AS9: 3213.3956 | AT9: 3191.8042 | AU9: 3170.8278 | AV9: 3150.4359 | AW9: 3130.6003 | AX9: 3111.2949 | AY9: 3092.4949 | AZ9: 3074.1776 | BA9: 3056.3212
A10: PP08 | B10: 4000 | C10: 3758.091 | D10: 3623.4233 | E10: 3530.812 | F10: 3460.6103 | G10: 3404.2887 | H10: 3357.3852 | I10: 3317.2782 | J10: 3282.2992 | K10: 3251.3221 | L10: 3223.5518 | M10: 3198.4066 | N10: 3175.4486 | O10: 3154.3397 | P10: 3134.814 | Q10: 3116.6583 | R10: 3099.6995 | S10: 3083.7948 | T10: 3068.8253 | U10: 3054.691 | V10: 3041.307 | W10: 3028.6002 | X10: 3016.508 | Y10: 3004.9758 | Z10: 2993.9558 | AA10: 2983.4062 | AB10: 2973.2899 | AC10: 2963.5739 | AD10: 2954.2291 | AE10: 2945.2291 | AF10: 2936.5503 | AG10: 2928.1714 | AH10: 2920.0732 | AI10: 2912.2382 | AJ10: 2904.6504 | AK10: 2897.2953 | AL10: 2890.1597 | AM10: 2883.2312 | AN10: 2876.4987 | AO10: 2869.9517 | AP10: 2863.5808 | AQ10: 2857.3771 | AR10: 2851.3323 | AS10: 2845.4388 | AT10: 2839.6896 | AU10: 2834.0779 | AV10: 2828.5977 | AW10: 2823.2431 | AX10: 2818.0088 | AY10: 2812.8896 | AZ10: 2807.8809 | BA10: 2802.978
A11: PP09 | B11: 5000 | C11: 4322.6862 | D11: 3969.8541 | E11: 3737.1231 | F11: 3566.0408 | G11: 3432.0866 | H11: 3322.7634 | I11: 3230.8821 | J11: 3151.9482 | K11: 3082.975 | L11: 3021.8823 | M11: 2967.1667 | N11: 2917.7085 | O11: 2872.6527 | P11: 2831.3323 | Q11: 2793.2178 | R11: 2757.8823 | S11: 2724.9766 | T11: 2694.2119 | U11: 2665.3467 | V11: 2638.1771 | W11: 2612.5297 | X11: 2588.2556 | Y11: 2565.2261 | Z11: 2543.3293 | AA11: 2522.4676 | AB11: 2502.5549 | AC11: 2483.5152 | AD11: 2465.281 | AE11: 2447.7922 | AF11: 2430.9949 | AG11: 2414.8408 | AH11: 2399.2863 | AI11: 2384.2919 | AJ11: 2369.8219 | AK11: 2355.8437 | AL11: 2342.3276 | AM11: 2329.2465 | AN11: 2316.5754 | AO11: 2304.2914 | AP11: 2292.3736 | AQ11: 2280.8024 | AR11: 2269.5598 | AS11: 2258.6292 | AT11: 2247.9952 | AU11: 2237.6433 | AV11: 2227.5602 | AW11: 2217.7334 | AX11: 2208.1513 | AY11: 2198.8029 | AZ11: 2189.6781 | BA11: 2180.7672
A12: PP10 | B12: 6000 | C12: 5223.3034 | D12: 4816.4494 | E12: 4547.1497 | F12: 4348.678 | G12: 4192.9627 | H12: 4065.6655 | I12: 3958.5237 | J12: 3866.3641 | K12: 3785.7441 | L12: 3714.2635 | M12: 3650.1861 | N12: 3592.2171 | O12: 3539.3674 | P12: 3490.8646 | Q12: 3446.0951 | R12: 3404.5637 | S12: 3365.8654 | T12: 3329.6649 | U12: 3295.6816 | V12: 3263.6787 | W12: 3233.4542 | X12: 3204.8351 | Y12: 3177.6715 | Z12: 3151.8334 | AA12: 3127.2066 | AB12: 3103.6911 | AC12: 3081.1983 | AD12: 3059.6493 | AE12: 3038.9741 | AF12: 3019.1098 | AG12: 3000 | AH12: 2981.5937 | AI12: 2963.8449 | AJ12: 2946.7117 | AK12: 2930.1561 | AL12: 2914.1433 | AM12: 2898.6417 | AN12: 2883.622 | AO12: 2869.0575 | AP12: 2854.9235 | AQ12: 2841.1973 | AR12: 2827.8577 | AS12: 2814.8854 | AT12: 2802.2621 | AU12: 2789.971 | AV12: 2777.9964 | AW12: 2766.3237 | AX12: 2754.9393 | AY12: 2743.8303 | AZ12: 2732.9848 | BA12: 2722.3915
A13: PP11 | B13: 1750 | C13: 1702.1462 | D13: 1674.7624 | E13: 1655.6009 | F13: 1640.8892 | G13: 1628.9659 | H13: 1618.9526 | I13: 1610.3284 | J13: 1602.7595 | K13: 1596.019 | L13: 1589.9459 | M13: 1584.4218 | N13: 1579.357 | O13: 1574.6822 | P13: 1570.3425 | Q13: 1566.2939 | R13: 1562.5002 | S13: 1558.9319 | T13: 1555.5641 | U13: 1552.3757 | V13: 1549.3491 | W13: 1546.4687 | X13: 1543.7214 | Y13: 1541.0957 | Z13: 1538.5813 | AA13: 1536.1694 | AB13: 1533.8521 | AC13: 1531.6225 | AD13: 1529.4741 | AE13: 1527.4014 | AF13: 1525.3994 | AG13: 1523.4635 | AH13: 1521.5895 | AI13: 1519.7736 | AJ13: 1518.0124 | AK13: 1516.3028 | AL13: 1514.6419 | AM13: 1513.0271 | AN13: 1511.4558 | AO13: 1509.9259 | AP13: 1508.4353 | AQ13: 1506.982 | AR13: 1505.5643 | AS13: 1504.1805 | AT13: 1502.8289 | AU13: 1501.5083 | AV13: 1500.2172 | AW13: 1498.9543 | AX13: 1497.7185 | AY13: 1496.5087 | AZ13: 1495.3238 | BA13: 1494.1628
A14: PP12 | B14: 2200 | C14: 2081.3268 | D14: 2014.8976 | E14: 1969.0552 | F14: 1934.2165 | G14: 1906.2093 | H14: 1882.8462 | I14: 1862.8397 | J14: 1845.3693 | K14: 1829.8803 | L14: 1815.9809 | M14: 1803.3839 | N14: 1791.8729 | O14: 1781.281 | P14: 1771.4764 | Q14: 1762.3537 | R14: 1753.8271 | S14: 1745.8257 | T14: 1738.2906 | U14: 1731.1722 | V14: 1724.4283 | W14: 1718.0226 | X14: 1711.9239 | Y14: 1706.1051 | Z14: 1700.5425 | AA14: 1695.2151 | AB14: 1690.1046 | AC14: 1685.1945 | AD14: 1680.4703 | AE14: 1675.9188 | AF14: 1671.5283 | AG14: 1667.2882 | AH14: 1663.1889 | AI14: 1659.2215 | AJ14: 1655.3782 | AK14: 1651.6517 | AL14: 1648.0354 | AM14: 1644.5232 | AN14: 1641.1093 | AO14: 1637.7887 | AP14: 1634.5566 | AQ14: 1631.4086 | AR14: 1628.3404 | AS14: 1625.3484 | AT14: 1622.4289 | AU14: 1619.5787 | AV14: 1616.7946 | AW14: 1614.0738 | AX14: 1611.4135 | AY14: 1608.8112 | AZ14: 1606.2645 | BA14: 1603.7712
... A16: PP14 | B16: 3200 | C16: 2924.2606 | D16: 2774.1134 | E16: 2672.2813 | F16: 2595.8756 | G16: 2535.0721 | H16: 2484.7759 | I16: 2442.0147 | J16: 2404.9079 | K16: 2372.1928 | L16: 2342.9819 | M16: 2316.6286 | N16: 2292.6478 | O16: 2270.6664 | P16: 2250.3917 | Q16: 2231.5899 | R16: 2214.0714 | S16: 2197.6805 | T16: 2182.2877 | U16: 2167.7844 | V16: 2154.0782 | W16: 2141.0905 | X16: 2128.7534 | Y16: 2117.0081 | Z16: 2105.8032 | AA16: 2095.0937 | AB16: 2084.8398 | AC16: 2075.0064 | AD16: 2065.562 | AE16: 2056.4787 | AF16: 2047.7313 | AG16: 2039.297 | AH16: 2031.1555 | AI16: 2023.2881 | AJ16: 2015.6779 | AK16: 2008.3095 | AL16: 2001.1689 | AM16: 1994.2432 | AN16: 1987.5203 | AO16: 1980.9895 | AP16: 1974.6407 | AQ16: 1968.4644 | AR16: 1962.4522 | AS16: 1956.5959 | AT16: 1950.8881 | AU16: 1945.3218 | AV16: 1939.8907 | AW16: 1934.5886 | AX16: 1929.4098 | AY16: 1924.3492 | AZ16: 1919.4016 | BA16: 1914.5625

Sheet FlowbackRates
A1: =_xlfn.CONCAT( "Table of Flowback Rate Forecasts by Pads [",VLOOKUP("volume", Units!$A$2:$B$11, 2, FALSE),"/", VLOOKUP("time", Units!$A$2:$B$11, 2, FALSE),"]") -> Table of Flowback Rate Forecasts by Pads [bbl/day]
A2: CompletionsPads | B2: T01 | C2: T02 | D2: T03 | E2: T04 | F2: T05 | G2: T06 | H2: T07 | I2: T08 | J2: T09 | K2: T10 | L2: T11 | M2: T12 | N2: T13 | O2: T14 | P2: T15 | Q2: T16 | R2: T17 | S2: T18 | T2: T19 | U2: T20 | V2: T21 | W2: T22 | X2: T23 | Y2: T24 | Z2: T25 | AA2: T26 | AB2: T27 | AC2: T28 | AD2: T29 | AE2: T30 | AF2: T31 | AG2: T32 | AH2: T33 | AI2: T34 | AJ2: T35 | AK2: T36 | AL2: T37 | AM2: T38 | AN2: T39 | AO2: T40 | AP2: T41 | AQ2: T42 | AR2: T43 | AS2: T44 | AT2: T45 | AU2: T46 | AV2: T47 | AW2: T48 | AX2: T49 | AY2: T50 | AZ2: T51 | BA2: T52
A3: CP01 | N3: =8*4000 -> 32000 | O3: =$N3*(VALUE(RIGHT(C$2,2)))^(-0.35) -> 25106.691 | P3: =$N3*(VALUE(RIGHT(D$2,2)))^(-0.35) -> 21784.999 | Q3: =$N3*(VALUE(RIGHT(E$2,2)))^(-0.35) -> 19698.311 | R3: =$N3*(VALUE(RIGHT(F$2,2)))^(-0.35) -> 18218.41 | S3: =$N3*(VALUE(RIGHT(G$2,2)))^(-0.35) -> 17092.164 | T3: =$N3*(VALUE(RIGHT(H$2,2)))^(-0.35) -> 16194.43 | U3: =$N3*(VALUE(RIGHT(I$2,2)))^(-0.35) -> 15454.981 | V3: =$N3*(VALUE(RIGHT(J$2,2)))^(-0.35) -> 14830.818 | ... BA3: =$N3*(VALUE(RIGHT(AO$2,2)))^(-0.35) -> 8798.9121
A4: CP02 | AL4: =8*4000 -> 32000 | AM4: =$AL4*(VALUE(RIGHT(C$2,2)))^(-0.35) -> 25106.691 | AN4: =$AL4*(VALUE(RIGHT(D$2,2)))^(-0.35) -> 21784.999 | AO4: =$AL4*(VALUE(RIGHT(E$2,2)))^(-0.35) -> 19698.311 | AP4: =$AL4*(VALUE(RIGHT(F$2,2)))^(-0.35) -> 18218.41 | AQ4: =$AL4*(VALUE(RIGHT(G$2,2)))^(-0.35) -> 17092.164 | AR4: =$AL4*(VALUE(RIGHT(H$2,2)))^(-0.35) -> 16194.43 | AS4: =$AL4*(VALUE(RIGHT(I$2,2)))^(-0.35) -> 15454.981 | AT4: =$AL4*(VALUE(RIGHT(J$2,2)))^(-0.35) -> 14830.818 | ... BA4: =$AL4*(VALUE(RIGHT(Q$2,2)))^(-0.35) -> 12125.733
A5: CP03

Sheet WellPressure
A1: =_xlfn.CONCAT("Well pressure at production or completions pad [",VLOOKUP("pressure", Units!$A$2:$B$11, 2, FALSE),"]") -> Well pressure at production or completions pad [psi] | E1: Flow-pressure assumption | H1: 150 psi for 15000 bbl/day and 15 psi for 1500 bbl/day | O1: Flow multiplier | Q1: 0.01
A2: NODES | B2: T01 | C2: T02 | D2: T03 | E2: T04 | F2: T05 | G2: T06 | H2: T07 | I2: T08 | J2: T09 | K2: T10 | L2: T11 | M2: T12 | N2: T13 | O2: T14 | P2: T15 | Q2: T16 | R2: T17 | S2: T18 | T2: T19 | U2: T20 | V2: T21 | W2: T22 | X2: T23 | Y2: T24 | Z2: T25 | AA2: T26 | AB2: T27 | AC2: T28 | AD2: T29 | AE2: T30 | AF2: T31 | AG2: T32 | AH2: T33 | AI2: T34 | AJ2: T35 | AK2: T36 | AL2: T37 | AM2: T38 | AN2: T39 | AO2: T40 | AP2: T41 | AQ2: T42 | AR2: T43 | AS2: T44 | AT2: T45 | AU2: T46 | AV2: T47 | AW2: T48 | AX2: T49 | AY2: T50 | AZ2: T51 | BA2: T52
A3: PP01 | B3: 50 | C3: =$B3*(VALUE(RIGHT(C$2,2)))^(-0.21) -> 43.226862 | D3: =$B3*(VALUE(RIGHT(D$2,2)))^(-0.21) -> 39.698541 | E3: =$B3*(VALUE(RIGHT(E$2,2)))^(-0.21) -> 37.371231 | F3: =$B3*(VALUE(RIGHT(F$2,2)))^(-0.21) -> 35.660408 | G3: =$B3*(VALUE(RIGHT(G$2,2)))^(-0.21) -> 34.320866 | H3: =$B3*(VALUE(RIGHT(H$2,2)))^(-0.21) -> 33.227634 | I3: =$B3*(VALUE(RIGHT(I$2,2)))^(-0.21) -> 32.308821 | J3: =$B3*(VALUE(RIGHT(J$2,2)))^(-0.21) -> 31.519482 | ... BA3: =$B3*(VALUE(RIGHT(BA$2,2)))^(-0.21) -> 21.807672
A4: PP02 | B4: 130 | C4: =$B4*(VALUE(RIGHT(C$2,2)))^(-0.35) -> 101.99593 | D4: =$B4*(VALUE(RIGHT(D$2,2)))^(-0.35) -> 88.501557 | E4: =$B4*(VALUE(RIGHT(E$2,2)))^(-0.35) -> 80.024387 | F4: =$B4*(VALUE(RIGHT(F$2,2)))^(-0.35) -> 74.012292 | G4: =$B4*(VALUE(RIGHT(G$2,2)))^(-0.35) -> 69.436915 | H4: =$B4*(VALUE(RIGHT(H$2,2)))^(-0.35) -> 65.789872 | I4: =$B4*(VALUE(RIGHT(I$2,2)))^(-0.35) -> 62.785861 | J4: =$B4*(VALUE(RIGHT(J$2,2)))^(-0.35) -> 60.250197 | ... BA4: =$B4*(VALUE(RIGHT(BA$2,2)))^(-0.35) -> 32.609353
A5: PP03 | B5: 80 | C5: =$B5*(VALUE(RIGHT(C$2,2)))^(-0.25) -> 67.271713 | D5: =$B5*(VALUE(RIGHT(D$2,2)))^(-0.25) -> 60.786855 | E5: =$B5*(VALUE(RIGHT(E$2,2)))^(-0.25) -> 56.568542 | F5: =$B5*(VALUE(RIGHT(F$2,2)))^(-0.25) -> 53.499224 | G5: =$B5*(VALUE(RIGHT(G$2,2)))^(-0.25) -> 51.115448 | H5: =$B5*(VALUE(RIGHT(H$2,2)))^(-0.25) -> 49.183052 | I5: =$B5*(VALUE(RIGHT(I$2,2)))^(-0.25) -> 47.568285 | J5: =$B5*(VALUE(RIGHT(J$2,2)))^(-0.25) -> 46.188022 | ... BA5: =$B5*(VALUE(RIGHT(BA$2,2)))^(-0.25) -> 29.791279
A6: PP04 | B6: 20 | C6: =$B6*(VALUE(RIGHT(C$2,2)))^(-0.02) -> 19.724654 | D6: =$B6*(VALUE(RIGHT(D$2,2)))^(-0.02) -> 19.565348 | E6: =$B6*(VALUE(RIGHT(E$2,2)))^(-0.02) -> 19.453099 | F6: =$B6*(VALUE(RIGHT(F$2,2)))^(-0.02) -> 19.366476 | G6: =$B6*(VALUE(RIGHT(G$2,2)))^(-0.02) -> 19.295986 | H6: =$B6*(VALUE(RIGHT(H$2,2)))^(-0.02) -> 19.236588 | I6: =$B6*(VALUE(RIGHT(I$2,2)))^(-0.02) -> 19.185282 | J6: =$B6*(VALUE(RIGHT(J$2,2)))^(-0.02) -> 19.140142 | ... BA6: =$B6*(VALUE(RIGHT(BA$2,2)))^(-0.02) -> 18.480339
A7: PP05 | B7: 15 | C7: =$B7*(VALUE(RIGHT(C$2,2)))^(-0.01) -> 14.896387 | D7: =$B7*(VALUE(RIGHT(D$2,2)))^(-0.01) -> 14.83611 | E7: =$B7*(VALUE(RIGHT(E$2,2)))^(-0.01) -> 14.793491 | F7: =$B7*(VALUE(RIGHT(F$2,2)))^(-0.01) -> 14.760517 | G7: =$B7*(VALUE(RIGHT(G$2,2)))^(-0.01) -> 14.73363 | H7: =$B7*(VALUE(RIGHT(H$2,2)))^(-0.01) -> 14.710935 | I7: =$B7*(VALUE(RIGHT(I$2,2)))^(-0.01) -> 14.691304 | J7: =$B7*(VALUE(RIGHT(J$2,2)))^(-0.01) -> 14.674011 | ... BA7: =$B7*(VALUE(RIGHT(BA$2,2)))^(-0.01) -> 14.41887
A8: PP06 | B8: 70 | C8: =$B8*(VALUE(RIGHT(C$2,2)))^(-0.17) -> 62.218988 | D8: =$B8*(VALUE(RIGHT(D$2,2)))^(-0.17) -> 58.07476 | E8: =$B8*(VALUE(RIGHT(E$2,2)))^(-0.17) -> 55.302892 | F8: =$B8*(VALUE(RIGHT(F$2,2)))^(-0.17) -> 53.244302 | G8: =$B8*(VALUE(RIGHT(G$2,2)))^(-0.17) -> 51.619326 | H8: =$B8*(VALUE(RIGHT(H$2,2)))^(-0.17) -> 50.28418 | I8: =$B8*(VALUE(RIGHT(I$2,2)))^(-0.17) -> 49.155571 | J8: =$B8*(VALUE(RIGHT(J$2,2)))^(-0.17) -> 48.181111 | ... BA8: =$B8*(VALUE(RIGHT(BA$2,2)))^(-0.17) -> 35.75835
A9: PP07 | B9: 100 | C9: =$B9*(VALUE(RIGHT(C$2,2)))^(-0.3) -> 81.22524 | D9: =$B9*(VALUE(RIGHT(D$2,2)))^(-0.3) -> 71.922309 | E9: =$B9*(VALUE(RIGHT(E$2,2)))^(-0.3) -> 65.975396 | F9: =$B9*(VALUE(RIGHT(F$2,2)))^(-0.3) -> 61.703386 | G9: =$B9*(VALUE(RIGHT(G$2,2)))^(-0.3) -> 58.419068 | H9: =$B9*(VALUE(RIGHT(H$2,2)))^(-0.3) -> 55.778983 | I9: =$B9*(VALUE(RIGHT(I$2,2)))^(-0.3) -> 53.588673 | J9: =$B9*(VALUE(RIGHT(J$2,2)))^(-0.3) -> 51.728186 | ... BA9: =$B9*(VALUE(RIGHT(BA$2,2)))^(-0.3) -> 30.563212
A10: PP08 | B10: 40 | C10: =$B10*(VALUE(RIGHT(C$2,2)))^(-0.09) -> 37.58091 | D10: =$B10*(VALUE(RIGHT(D$2,2)))^(-0.09) -> 36.234233 | E10: =$B10*(VALUE(RIGHT(E$2,2)))^(-0.09) -> 35.30812 | F10: =$B10*(VALUE(RIGHT(F$2,2)))^(-0.09) -> 34.606103 | G10: =$B10*(VALUE(RIGHT(G$2,2)))^(-0.09) -> 34.042887 | H10: =$B10*(VALUE(RIGHT(H$2,2)))^(-0.09) -> 33.573852 | I10: =$B10*(VALUE(RIGHT(I$2,2)))^(-0.09) -> 33.172782 | J10: =$B10*(VALUE(RIGHT(J$2,2)))^(-0.09) -> 32.822992 | ... BA10: =$B10*(VALUE(RIGHT(BA$2,2)))^(-0.09) -> 28.02978
A11: PP09 | B11: 50 | C11: =$B11*(VALUE(RIGHT(C$2,2)))^(-0.21) -> 43.226862 | D11: =$B11*(VALUE(RIGHT(D$2,2)))^(-0.21) -> 39.698541 | E11: =$B11*(VALUE(RIGHT(E$2,2)))^(-0.21) -> 37.371231 | F11: =$B11*(VALUE(RIGHT(F$2,2)))^(-0.21) -> 35.660408 | G11: =$B11*(VALUE(RIGHT(G$2,2)))^(-0.21) -> 34.320866 | H11: =$B11*(VALUE(RIGHT(H$2,2)))^(-0.21) -> 33.227634 | I11: =$B11*(VALUE(RIGHT(I$2,2)))^(-0.21) -> 32.308821 | J11: =$B11*(VALUE(RIGHT(J$2,2)))^(-0.21) -> 31.519482 | ... BA11: =$B11*(VALUE(RIGHT(BA$2,2)))^(-0.21) -> 21.807672
A12: PP10 | B12: 60 | C12: =$B12*(VALUE(RIGHT(C$2,2)))^(-0.2) -> 52.233034 | D12: =$B12*(VALUE(RIGHT(D$2,2)))^(-0.2) -> 48.164494 | E12: =$B12*(VALUE(RIGHT(E$2,2)))^(-0.2) -> 45.471497 | F12: =$B12*(VALUE(RIGHT(F$2,2)))^(-0.2) -> 43.48678 | G12: =$B12*(VALUE(RIGHT(G$2,2)))^(-0.2) -> 41.929627 | H12: =$B12*(VALUE(RIGHT(H$2,2)))^(-0.2) -> 40.656655 | I12: =$B12*(VALUE(RIGHT(I$2,2)))^(-0.2) -> 39.585237 | J12: =$B12*(VALUE(RIGHT(J$2,2)))^(-0.2) -> 38.663641 | ... BA12: =$B12*(VALUE(RIGHT(BA$2,2)))^(-0.2) -> 27.223915
A13: PP11 | B13: 17.5 | C13: =$B13*(VALUE(RIGHT(C$2,2)))^(-0.04) -> 17.021462 | D13: =$B13*(VALUE(RIGHT(D$2,2)))^(-0.04) -> 16.747624 | E13: =$B13*(VALUE(RIGHT(E$2,2)))^(-0.04) -> 16.556009 | F13: =$B13*(VALUE(RIGHT(F$2,2)))^(-0.04) -> 16.408892 | G13: =$B13*(VALUE(RIGHT(G$2,2)))^(-0.04) -> 16.289659 | H13: =$B13*(VALUE(RIGHT(H$2,2)))^(-0.04) -> 16.189526 | I13: =$B13*(VALUE(RIGHT(I$2,2)))^(-0.04) -> 16.103284 | J13: =$B13*(VALUE(RIGHT(J$2,2)))^(-0.04) -> 16.027595 | ... BA13: =$B13*(VALUE(RIGHT(BA$2,2)))^(-0.04) -> 14.941628
A14: PP12 | B14: 22 | C14: =$B14*(VALUE(RIGHT(C$2,2)))^(-0.08) -> 20.813268 | D14: =$B14*(VALUE(RIGHT(D$2,2)))^(-0.08) -> 20.148976 | E14: =$B14*(VALUE(RIGHT(E$2,2)))^(-0.08) -> 19.690552 | F14: =$B14*(VALUE(RIGHT(F$2,2)))^(-0.08) -> 19.342165 | G14: =$B14*(VALUE(RIGHT(G$2,2)))^(-0.08) -> 19.062093 | H14: =$B14*(VALUE(RIGHT(H$2,2)))^(-0.08) -> 18.828462 | I14: =$B14*(VALUE(RIGHT(I$2,2)))^(-0.08) -> 18.628397 | J14: =$B14*(VALUE(RIGHT(J$2,2)))^(-0.08) -> 18.453693 | ... BA14: =$B14*(VALUE(RIGHT(BA$2,2)))^(-0.08) -> 16.037712
A15: PP13 | B15: 16 | C15: =$B15*(VALUE(RIGHT(C$2,2)))^(-0.03) -> 15.670725 | D15: =$B15*(VALUE(RIGHT(D$2,2)))^(-0.03) -> 15.481261 | E15: =$B15*(VALUE(RIGHT(E$2,2)))^(-0.03) -> 15.348226 | F15: =$B15*(VALUE(RIGHT(F$2,2)))^(-0.03) -> 15.245823 | G15: =$B15*(VALUE(RIGHT(G$2,2)))^(-0.03) -> 15.162662 | H15: =$B15*(VALUE(RIGHT(H$2,2)))^(-0.03) -> 15.092704 | I15: =$B15*(VALUE(RIGHT(I$2,2)))^(-0.03) -> 15.032364 | J15: =$B15*(VALUE(RIGHT(J$2,2)))^(-0.03) -> 14.979341 | ... BA15: =$B15*(VALUE(RIGHT(BA$2,2)))^(-0.03) -> 14.211499
A16: PP14 | B16: 32 | C16: =$B16*(VALUE(RIGHT(C$2,2)))^(-0.13) -> 29.242606 | D16: =$B16*(VALUE(RIGHT(D$2,2)))^(-0.13) -> 27.741134 | E16: =$B16*(VALUE(RIGHT(E$2,2)))^(-0.13) -> 26.722813 | F16: =$B16*(VALUE(RIGHT(F$2,2)))^(-0.13) -> 25.958756 | G16: =$B16*(VALUE(RIGHT(G$2,2)))^(-0.13) -> 25.350721 | H16: =$B16*(VALUE(RIGHT(H$2,2)))^(-0.13) -> 24.847759 | I16: =$B16*(VALUE(RIGHT(I$2,2)))^(-0.13) -> 24.420147 | J16: =$B16*(VALUE(RIGHT(J$2,2)))^(-0.13) -> 24.049079 | ... BA16: =$B16*(VALUE(RIGHT(BA$2,2)))^(-0.13) -> 19.145625
A17: CP01 | N17: 320 | O17: =$N17*(VALUE(RIGHT(C$2,2)))^(-0.35) -> 251.06691 | P17: =$N17*(VALUE(RIGHT(D$2,2)))^(-0.35) -> 217.84999 | Q17: =$N17*(VALUE(RIGHT(E$2,2)))^(-0.35) -> 196.98311 | R17: =$N17*(VALUE(RIGHT(F$2,2)))^(-0.35) -> 182.1841 | S17: =$N17*(VALUE(RIGHT(G$2,2)))^(-0.35) -> 170.92164 | T17: =$N17*(VALUE(RIGHT(H$2,2)))^(-0.35) -> 161.9443 | U17: =$N17*(VALUE(RIGHT(I$2,2)))^(-0.35) -> 154.54981 | V17: =$N17*(VALUE(RIGHT(J$2,2)))^(-0.35) -> 148.30818 | ... BA17: =$N17*(VALUE(RIGHT(AO$2,2)))^(-0.35) -> 87.989121
A18: CP02 | AL18: 320 | AM18: =$AL18*(VALUE(RIGHT(C$2,2)))^(-0.35) -> 251.06691 | AN18: =$AL18*(VALUE(RIGHT(D$2,2)))^(-0.35) -> 217.84999 | AO18: =$AL18*(VALUE(RIGHT(E$2,2)))^(-0.35) -> 196.98311 | AP18: =$AL18*(VALUE(RIGHT(F$2,2)))^(-0.35) -> 182.1841 | AQ18: =$AL18*(VALUE(RIGHT(G$2,2)))^(-0.35) -> 170.92164 | AR18: =$AL18*(VALUE(RIGHT(H$2,2)))^(-0.35) -> 161.9443 | AS18: =$AL18*(VALUE(RIGHT(I$2,2)))^(-0.35) -> 154.54981 | AT18: =$AL18*(VALUE(RIGHT(J$2,2)))^(-0.35) -> 148.30818 | ... BA18: =$AL18*(VALUE(RIGHT(Q$2,2)))^(-0.35) -> 121.25733
A19: CP03

Sheet InitialPipelineCapacity
A1: =_xlfn.CONCAT( "Table of Initial Pipeline Capacity between Sites [",VLOOKUP("volume", Units!$A$2:$B$11, 2, FALSE),"/", VLOOKUP("time", Units!$A$2:$B$11, 2, FALSE),"]") -> Table of Initial Pipeline Capacity between Sites [bbl/day]
A2: NODES | B2: N01 | C2: N02 | D2: N03 | E2: N04 | F2: N05 | G2: N06 | H2: N07 | I2: N08 | J2: N09 | K2: N10 | L2: N11 | M2: N12 | N2: N13 | O2: N14 | P2: N15 | Q2: N16 | R2: N17 | S2: N18 | T2: N19 | U2: N20 | V2: N21 | W2: N22 | X2: N23 | Y2: N24 | Z2: N25 | AA2: N26 | AB2: N27 | AC2: N28 | AD2: K01 | AE2: K02 | AF2: K03 | AG2: K04 | AH2: K05 | AI2: R02 | AJ2: R03 | AK2: R04 | AL2: R05 | AM2: S02 | AN2: S04 | AO2: S05 | AP2: CP01 | AQ2: CP02 | AR2: CP03
A3: PP01 | B3: 14206 | C3: 0 | D3: 0 | E3: 0 | F3: 0 | G3: 0 | H3: 0 | I3: 0 | J3: 0 | K3: 0 | L3: 0 | M3: 0 | N3: 0 | O3: 0 | P3: 0 | Q3: 0 | R3: 0 | S3: 0 | T3: 0 | U3: 0 | V3: 0 | W3: 0 | X3: 0 | Y3: 0 | Z3: 0 | AA3: 0 | AB3: 0 | AC3: 0 | AD3: 0 | AE3: 0 | AF3: 0 | AG3: 0 | AH3: 0 | AI3: 0 | AJ3: 0 | AK3: 0 | AL3: 0 | AM3: 0 | AN3: 0 | AO3: 0 | AP3: 0 | AQ3: 0 | AR3: 0
A4: PP02 | B4: 0 | C4: 0 | D4: 0 | E4: 0 | F4: 14206 | G4: 0 | H4: 0 | I4: 0 | J4: 0 | K4: 0 | L4: 0 | M4: 0 | N4: 0 | O4: 0 | P4: 0 | Q4: 0 | R4: 0 | S4: 0 | T4: 0 | U4: 0 | V4: 0 | W4: 0 | X4: 0 | Y4: 0 | Z4: 0 | AA4: 0 | AB4: 0 | AC4: 0 | AD4: 0 | AE4: 0 | AF4: 0 | AG4: 0 | AH4: 0 | AI4: 0 | AJ4: 0 | AK4: 0 | AL4: 0 | AM4: 0 | AN4: 0 | AO4: 0 | AP4: 0 | AQ4: 0 | AR4: 0
A5: PP03 | B5: 0 | C5: 0 | D5: 0 | E5: 0 | F5: 0 | G5: 14206 | H5: 0 | I5: 0 | J5: 0 | K5: 0 | L5: 0 | M5: 0 | N5: 0 | O5: 0 | P5: 0 | Q5: 0 | R5: 0 | S5: 0 | T5: 0 | U5: 0 | V5: 0 | W5: 0 | X5: 0 | Y5: 0 | Z5: 0 | AA5: 0 | AB5: 0 | AC5: 0 | AD5: 0 | AE5: 0 | AF5: 0 | AG5: 0 | AH5: 0 | AI5: 0 | AJ5: 0 | AK5: 0 | AL5: 0 | AM5: 0 | AN5: 0 | AO5: 0 | AP5: 0 | AQ5: 0 | AR5: 0
A6: PP04 | B6: 0 | C6: 0 | D6: 0 | E6: 0 | F6: 0 | G6: 0 | H6: 0 | I6: 0 | J6: 0 | K6: 0 | L6: 14286 | M6: 0 | N6: 0 | O6: 0 | P6: 0 | Q6: 0 | R6: 0 | S6: 0 | T6: 0 | U6: 0 | V6: 0 | W6: 0 | X6: 0 | Y6: 0 | Z6: 0 | AA6: 0 | AB6: 0 | AC6: 0 | AD6: 0 | AE6: 0 | AF6: 0 | AG6: 0 | AH6: 0 | AI6: 0 | AJ6: 0 | AK6: 0 | AL6: 0 | AM6: 0 | AN6: 0 | AO6: 0 | AP6: 0 | AQ6: 0 | AR6: 0
A7: PP05 | B7: 0 | C7: 0 | D7: 0 | E7: 0 | F7: 0 | G7: 0 | H7: 0 | I7: 0 | J7: 0 | K7: 0 | L7: 0 | M7: 0 | N7: 0 | O7: 0 | P7: 0 | Q7: 0 | R7: 0 | S7: 0 | T7: 0 | U7: 0 | V7: 0 | W7: 0 | X7: 0 | Y7: 0 | Z7: 0 | AA7: 0 | AB7: 0 | AC7: 0 | AD7: 0 | AE7: 0 | AF7: 0 | AG7: 0 | AH7: 0 | AI7: 0 | AJ7: 0 | AK7: 0 | AL7: 0 | AM7: 0 | AN7: 0 | AO7: 0 | AP7: 0 | AQ7: 0 | AR7: 0
A8: PP06 | B8: 0 | C8: 0 | D8: 0 | E8: 0 | F8: 0 | G8: 0 | H8: 0 | I8: 0 | J8: 0 | K8: 0 | L8: 0 | M8: 0 | N8: 0 | O8: 0 | P8: 0 | Q8: 14206 | R8: 0 | S8: 0 | T8: 0 | U8: 0 | V8: 0 | W8: 0 | X8: 0 | Y8: 0 | Z8: 0 | AA8: 0 | AB8: 0 | AC8: 0 | AD8: 0 | AE8: 0 | AF8: 0 | AG8: 0 | AH8: 0 | AI8: 0 | AJ8: 0 | AK8: 0 | AL8: 0 | AM8: 0 | AN8: 0 | AO8: 0 | AP8: 0 | AQ8: 0 | AR8: 0
A9: PP07 | B9: 0 | C9: 0 | D9: 0 | E9: 0 | F9: 0 | G9: 0 | H9: 0 | I9: 0 | J9: 0 | K9: 0 | L9: 0 | M9: 0 | N9: 0 | O9: 0 | P9: 14206 | Q9: 0 | R9: 0 | S9: 0 | T9: 0 | U9: 0 | V9: 0 | W9: 0 | X9: 0 | Y9: 0 | Z9: 0 | AA9: 0 | AB9: 0 | AC9: 0 | AD9: 0 | AE9: 0 | AF9: 0 | AG9: 0 | AH9: 0 | AI9: 0 | AJ9: 0 | AK9: 0 | AL9: 0 | AM9: 0 | AN9: 0 | AO9: 0 | AP9: 0 | AQ9: 0 | AR9: 0
A10: PP08 | B10: 0 | C10: 0 | D10: 0 | E10: 0 | F10: 0 | G10: 0 | H10: 0 | I10: 0 | J10: 0 | K10: 0 | L10: 0 | M10: 0 | N10: 0 | O10: 0 | P10: 0 | Q10: 0 | R10: 0 | S10: 14206 | T10: 0 | U10: 0 | V10: 0 | W10: 0 | X10: 0 | Y10: 0 | Z10: 0 | AA10: 0 | AB10: 0 | AC10: 0 | AD10: 0 | AE10: 0 | AF10: 0 | AG10: 0 | AH10: 0 | AI10: 0 | AJ10: 0 | AK10: 0 | AL10: 0 | AM10: 0 | AN10: 0 | AO10: 0 | AP10: 0 | AQ10: 0 | AR10: 0
A11: PP09 | B11: 0 | C11: 0 | D11: 0 | E11: 0 | F11: 0 | G11: 0 | H11: 0 | I11: 0 | J11: 0 | K11: 0 | L11: 0 | M11: 0 | N11: 0 | O11: 0 | P11: 0 | Q11: 0 | R11: 0 | S11: 0 | T11: 0 | U11: 0 | V11: 14206 | W11: 0 | X11: 0 | Y11: 0 | Z11: 0 | AA11: 0 | AB11: 0 | AC11: 0 | AD11: 0 | AE11: 0 | AF11: 0 | AG11: 0 | AH11: 0 | AI11: 0 | AJ11: 0 | AK11: 0 | AL11: 0 | AM11: 0 | AN11: 0 | AO11: 0 | AP11: 0 | AQ11: 0 | AR11: 0
A12: PP10 | B12: 0 | C12: 0 | D12: 0 | E12: 0 | F12: 0 | G12: 0 | H12: 0 | I12: 0 | J12: 0 | K12: 0 | L12: 0 | M12: 0 | N12: 0 | O12: 0 | P12: 0 | Q12: 0 | R12: 0 | S12: 0 | T12: 14206 | U12: 0 | V12: 0 | W12: 0 | X12: 0 | Y12: 0 | Z12: 0 | AA12: 0 | AB12: 0 | AC12: 0 | AD12: 0 | AE12: 0 | AF12: 0 | AG12: 0 | AH12: 0 | AI12: 0 | AJ12: 0 | AK12: 0 | AL12: 0 | AM12: 0 | AN12: 0 | AO12: 0 | AP12: 0 | AQ12: 0 | AR12: 0
A13: PP11 | B13: 0 | C13: 0 | D13: 0 | E13: 0 | F13: 0 | G13: 0 | H13: 0 | I13: 0 | J13: 0 | K13: 0 | L13: 0 | M13: 0 | N13: 0 | O13: 0 | P13: 0 | Q13: 0 | R13: 0 | S13: 0 | T13: 0 | U13: 0 | V13: 0 | W13: 0 | X13: 0 | Y13: 0 | Z13: 14206 | AA13: 0 | AB13: 0 | AC13: 0 | AD13: 0 | AE13: 0 | AF13: 0 | AG13: 0 | AH13: 0 | AI13: 0 | AJ13: 0 | AK13: 0 | AL13: 0 | AM13: 0 | AN13: 0 | AO13: 0 | AP13: 0 | AQ13: 0 | AR13: 0
A14: PP12 | B14: 0 | C14: 0 | D14: 0 | E14: 0 | F14: 0 | G14: 0 | H14: 0 | I14: 0 | J14: 0 | K14: 0 | L14: 0 | M14: 0 | N14: 0 | O14: 0 | P14: 0 | Q14: 0 | R14: 0 | S14: 0 | T14: 0 | U14: 0 | V14: 0 | W14: 0 | X14: 0 | Y14: 0 | Z14: 0 | AA14: 0 | AB14: 14206 | AC14: 0 | AD14: 0 | AE14: 0 | AF14: 0 | AG14: 0 | AH14: 0 | AI14: 0 | AJ14: 0 | AK14: 0 | AL14: 0 | AM14: 0 | AN14: 0 | AO14: 0 | AP14: 0 | AQ14: 0 | AR14: 0
... A20: N01 | B20: 0 | C20: 42857 | D20: 0 | E20: 0 | F20: 0 | G20: 0 | H20: 0 | I20: 0 | J20: 0 | K20: 0 | L20: 0 | M20: 0 | N20: 0 | O20: 0 | P20: 0 | Q20: 0 | R20: 0 | S20: 0 | T20: 0 | U20: 0 | V20: 0 | W20: 0 | X20: 0 | Y20: 0 | Z20: 0 | AA20: 0 | AB20: 0 | AC20: 0 | AD20: 42857 | AE20: 0 | AF20: 0 | AG20: 0 | AH20: 0 | AI20: 0 | AJ20: 0 | AK20: 0 | AL20: 0 | AM20: 0 | AN20: 0 | AO20: 0 | AP20: 0 | AQ20: 0 | AR20: 0
A21: N02 | C21: 0 | D21: 42857 | E21: 0 | F21: 42857 | G21: 0 | H21: 0 | I21: 0 | J21: 0 | K21: 0 | L21: 0 | M21: 0 | N21: 0 | O21: 0 | P21: 0 | Q21: 0 | R21: 0 | S21: 0 | T21: 0 | U21: 0 | V21: 0 | W21: 0 | X21: 0 | Y21: 0 | Z21: 0 | AA21: 0 | AB21: 0 | AC21: 0 | AD21: 0 | AE21: 0 | AF21: 0 | AG21: 0 | AH21: 0 | AI21: 0 | AJ21: 0 | AK21: 0 | AL21: 0 | AM21: 0 | AN21: 0 | AO21: 0 | AP21: 0 | AQ21: 0 | AR21: 0
A22: N03 | B22: 0 | D22: 0 | E22: 42857 | F22: 0 | G22: 0 | H22: 0 | I22: 0 | J22: 0 | K22: 0 | L22: 0 | M22: 0 | N22: 0 | O22: 0 | P22: 0 | Q22: 0 | R22: 0 | S22: 0 | T22: 0 | U22: 0 | V22: 0 | W22: 0 | X22: 0 | Y22: 0 | Z22: 0 | AA22: 0 | AB22: 0 | AC22: 0 | AD22: 0 | AE22: 0 | AF22: 0 | AG22: 0 | AH22: 0 | AI22: 0 | AJ22: 0 | AK22: 0 | AL22: 0 | AM22: 0 | AN22: 0 | AO22: 0 | AP22: 0 | AQ22: 0 | AR22: 0
A23: N04 | B23: 0 | C23: 0 | E23: 0 | F23: 0 | G23: 42857 | H23: 0 | I23: 0 | J23: 0 | K23: 0 | L23: 0 | M23: 0 | N23: 0 | O23: 0 | P23: 0 | Q23: 0 | R23: 0 | S23: 0 | T23: 0 | U23: 0 | V23: 0 | W23: 0 | X23: 0 | Y23: 0 | Z23: 0 | AA23: 0 | AB23: 0 | AC23: 0 | AD23: 0 | AE23: 42857 | AF23: 0 | AG23: 0 | AH23: 0 | AI23: 0 | AJ23: 0 | AK23: 0 | AL23: 0 | AM23: 0 | AN23: 0 | AO23: 0 | AP23: 0 | AQ23: 0 | AR23: 0
A24: N05 | B24: 0 | D24: 0 | E24: 0 | F24: 0 | G24: 0 | H24: 0 | I24: 42857 | J24: 0 | K24: 0 | L24: 0 | M24: 0 | N24: 0 | O24: 0 | P24: 0 | Q24: 0 | R24: 0 | S24: 0 | T24: 0 | U24: 0 | V24: 0 | W24: 0 | X24: 0 | Y24: 0 | Z24: 0 | AA24: 0 | AB24: 0 | AC24: 0 | AD24: 0 | AE24: 0 | AF24: 0 | AG24: 0 | AH24: 0 | AI24: 0 | AJ24: 0 | AK24: 0 | AL24: 0 | AM24: 0 | AN24: 0 | AO24: 0 | AP24: 0 | AQ24: 0 | AR24: 0
A25: N06 | B25: 0 | C25: 0 | D25: 0 | F25: 0 | G25: 0 | H25: 42857 | I25: 0 | J25: 0 | K25: 0 | L25: 0 | M25: 0 | N25: 0 | O25: 0 | P25: 0 | Q25: 0 | R25: 0 | S25: 0 | T25: 0 | U25: 0 | V25: 0 | W25: 0 | X25: 0 | Y25: 0 | Z25: 0 | AA25: 0 | AB25: 0 | AC25: 0 | AD25: 0 | AE25: 0 | AF25: 0 | AG25: 0 | AH25: 0 | AI25: 0 | AJ25: 0 | AK25: 0 | AL25: 0 | AM25: 0 | AN25: 0 | AO25: 0 | AP25: 0 | AQ25: 0 | AR25: 0
A26: N07 | B26: 0 | C26: 0 | D26: 0 | E26: 0 | F26: 0 | H26: 0 | I26: 42857 | J26: 35714 | K26: 0 | L26: 0 | M26: 0 | N26: 0 | O26: 0 | P26: 0 | Q26: 0 | R26: 0 | S26: 0 | T26: 0 | U26: 0 | V26: 0 | W26: 0 | X26: 0 | Y26: 0 | Z26: 0 | AA26: 0 | AB26: 0 | AC26: 0 | AD26: 0 | AE26: 0 | AF26: 0 | AG26: 0 | AH26: 0 | AI26: 0 | AJ26: 0 | AK26: 0 | AL26: 0 | AM26: 0 | AN26: 0 | AO26: 0 | AP26: 0 | AQ26: 0 | AR26: 0
A27: N08 | B27: 0 | C27: 0 | D27: 0 | E27: 0 | G27: 0 | I27: 0 | J27: 0 | K27: 0 | L27: 0 | M27: 0 | N27: 0 | O27: 0 | P27: 0 | Q27: 0 | R27: 0 | S27: 0 | T27: 0 | U27: 0 | V27: 0 | W27: 0 | X27: 0 | Y27: 0 | Z27: 0 | AA27: 0 | AB27: 0 | AC27: 0 | AD27: 0 | AE27: 0 | AF27: 0 | AG27: 0 | AH27: 0 | AI27: 0 | AJ27: 0 | AK27: 0 | AL27: 0 | AM27: 0 | AN27: 0 | AO27: 0 | AQ27: 0 | AR27: 0
A28: N09 | B28: 0 | C28: 0 | D28: 0 | E28: 0 | F28: 0 | G28: 0 | I28: 0 | J28: 0 | K28: 0 | L28: 35714 | M28: 0 | N28: 0 | O28: 0 | P28: 0 | Q28: 0 | R28: 0 | S28: 0 | T28: 0 | U28: 0 | V28: 0 | W28: 0 | X28: 0 | Y28: 0 | Z28: 0 | AA28: 0 | AB28: 0 | AC28: 0 | AD28: 0 | AE28: 0 | AF28: 0 | AG28: 0 | AH28: 0 | AI28: 0 | AJ28: 0 | AK28: 0 | AL28: 0 | AM28: 0 | AN28: 0 | AO28: 0 | AP28: 0 | AQ28: 0 | AR28: 0
A29: N10 | B29: 0 | C29: 0 | D29: 0 | E29: 0 | F29: 0 | G29: 0 | H29: 0 | I29: 0 | J29: 0 | K29: 0 | L29: 0 | M29: 0 | N29: 0 | O29: 0 | P29: 0 | Q29: 0 | R29: 0 | S29: 0 | T29: 0 | U29: 0 | V29: 0 | W29: 0 | X29: 0 | Y29: 0 | Z29: 0 | AA29: 0 | AB29: 0 | AC29: 0 | AD29: 0 | AE29: 0 | AF29: 0 | AG29: 0 | AH29: 0 | AI29: 0 | AJ29: 0 | AK29: 0 | AL29: 0 | AM29: 0 | AN29: 0 | AO29: 0 | AP29: 0 | AQ29: 0 | AR29: 0
A30: N11 | B30: 0 | C30: 0 | D30: 0 | E30: 0 | F30: 0 | G30: 0 | H30: 0 | I30: 0 | K30: 0 | L30: 0 | M30: 0 | N30: 35714 | O30: 0 | P30: 0 | Q30: 0 | R30: 0 | S30: 0 | T30: 0 | U30: 0 | V30: 0 | W30: 0 | X30: 0 | Y30: 0 | Z30: 0 | AA30: 0 | AB30: 0 | AC30: 0 | AD30: 0 | AE30: 0 | AF30: 0 | AG30: 0 | AH30: 0 | AI30: 0 | AJ30: 0 | AK30: 0 | AL30: 0 | AM30: 0 | AN30: 0 | AO30: 0 | AP30: 0 | AQ30: 0 | AR30: 0
A31: N12 | B31: 0 | C31: 0 | D31: 0 | E31: 0 | F31: 0 | G31: 0 | H31: 0 | I31: 0 | J31: 0 | K31: 0 | L31: 0 | M31: 0 | N31: 0 | O31: 0 | P31: 0 | Q31: 0 | R31: 0 | S31: 0 | T31: 0 | U31: 0 | V31: 0 | W31: 0 | X31: 0 | Y31: 0 | Z31: 0 | AA31: 0 | AB31: 0 | AC31: 0 | AD31: 0 | AE31: 0 | AF31: 0 | AG31: 0 | AH31: 0 | AI31: 0 | AJ31: 0 | AK31: 0 | AL31: 0 | AM31: 0 | AN31: 0 | AO31: 0 | AP31: 0 | AQ31: 0 | AR31: 0
A32: N13 | B32: 0 | C32: 0 | D32: 0 | E32: 0 | F32: 0 | G32: 0 | H32: 0 | I32: 0 | J32: 0 | K32: 0 | M32: 0 | N32: 0 | O32: 35714 | P32: 0 | Q32: 0 | R32: 0 | S32: 0 | T32: 0 | U32: 0 | V32: 0 | W32: 0 | X32: 0 | Y32: 0 | Z32: 0 | AA32: 0 | AB32: 0 | AC32: 0 | AD32: 0 | AE32: 0 | AF32: 0 | AG32: 0 | AH32: 0 | AI32: 0 | AJ32: 0 | AK32: 0 | AL32: 0 | AM32: 0 | AN32: 0 | AO32: 0 | AP32: 0 | AQ32: 0 | AR32: 0
A33: N14 | B33: 0 | C33: 0 | D33: 0 | E33: 0 | F33: 0 | G33: 0 | H33: 0 | I33: 0 | J33: 0 | K33: 0 | L33: 0 | M33: 0 | O33: 0 | P33: 0 | Q33: 0 | R33: 0 | S33: 0 | T33: 0 | U33: 0 | V33: 0 | W33: 0 | X33: 0 | Y33: 0 | Z33: 0 | AA33: 0 | AB33: 0 | AC33: 35714 | AD33: 0 | AE33: 0 | AF33: 0 | AG33: 0 | AH33: 0 | AI33: 0 | AJ33: 0 | AK33: 0 | AL33: 0 | AM33: 0 | AN33: 0 | AO33: 0 | AP33: 0 | AQ33: 0 | AR33: 0
A34: N15 | B34: 0 | C34: 0 | D34: 0 | E34: 0 | F34: 0 | G34: 0 | H34: 0 | I34: 0 | J34: 0 | K34: 0 | L34: 0 | M34: 0 | N34: 0 | O34: 0 | P34: 0 | Q34: 42857 | R34: 0 | S34: 0 | T34: 0 | U34: 0 | V34: 0 | W34: 0 | X34: 0 | Y34: 0 | Z34: 0 | AA34: 0 | AB34: 0 | AC34: 42857 | AD34: 0 | AE34: 0 | AF34: 0 | AG34: 0 | AH34: 0 | AI34: 0 | AJ34: 0 | AK34: 0 | AL34: 0 | AM34: 0 | AN34: 0 | AO34: 0 | AP34: 0 | AQ34: 0 | AR34: 0
A35: N16 | B35: 0 | C35: 0 | D35: 0 | E35: 0 | F35: 0 | G35: 0 | H35: 0 | I35: 0 | J35: 0 | K35: 0 | L35: 0 | M35: 0 | N35: 0 | O35: 0 | Q35: 0 | R35: 35714 | S35: 0 | T35: 0 | U35: 0 | V35: 0 | W35: 0 | X35: 0 | Y35: 0 | Z35: 0 | AA35: 0 | AB35: 0 | AC35: 0 | AD35: 0 | AE35: 0 | AF35: 0 | AG35: 0 | AH35: 0 | AI35: 0 | AJ35: 0 | AK35: 0 | AL35: 0 | AM35: 0 | AN35: 0 | AO35: 0 | AP35: 0 | AQ35: 0 | AR35: 0
A36: N17 | B36: 0 | C36: 0 | D36: 0 | E36: 0 | F36: 0 | G36: 0 | H36: 0 | I36: 0 | J36: 0 | K36: 0 | L36: 0 | M36: 0 | N36: 0 | O36: 0 | P36: 0 | R36: 0 | S36: 0 | T36: 0 | U36: 0 | V36: 0 | W36: 0 | X36: 0 | Y36: 0 | Z36: 0 | AA36: 0 | AB36: 0 | AC36: 0 | AD36: 0 | AE36: 0 | AF36: 0 | AG36: 0 | AH36: 0 | AI36: 0 | AJ36: 0 | AK36: 0 | AL36: 0 | AM36: 0 | AN36: 0 | AO36: 0 | AP36: 0 | AQ36: 0 | AR36: 0
A37: N18 | B37: 0 | C37: 0 | D37: 0 | E37: 0 | F37: 0 | G37: 0 | H37: 0 | I37: 0 | J37: 0 | K37: 0 | L37: 0 | M37: 0 | N37: 0 | O37: 0 | P37: 0 | Q37: 0 | R37: 0 | S37: 0 | T37: 42857 | U37: 0 | V37: 0 | W37: 0 | X37: 0 | Y37: 0 | Z37: 0 | AA37: 0 | AB37: 0 | AC37: 0 | AD37: 0 | AE37: 0 | AF37: 0 | AG37: 42857 | AH37: 0 | AI37: 0 | AJ37: 0 | AK37: 0 | AL37: 0 | AM37: 0 | AN37: 0 | AO37: 0 | AP37: 0 | AQ37: 0 | AR37: 0
A38: N19 | B38: 0 | C38: 0 | D38: 0 | E38: 0 | F38: 0 | G38: 0 | H38: 0 | I38: 0 | J38: 0 | K38: 0 | L38: 0 | M38: 0 | N38: 0 | O38: 0 | P38: 0 | Q38: 0 | R38: 0 | T38: 0 | U38: 0 | V38: 0 | W38: 42857 | X38: 0 | Y38: 0 | Z38: 0 | AA38: 0 | AB38: 0 | AC38: 0 | AD38: 0 | AE38: 0 | AF38: 0 | AG38: 0 | AH38: 0 | AI38: 0 | AJ38: 0 | AK38: 0 | AL38: 0 | AM38: 0 | AN38: 0 | AO38: 0 | AP38: 0 | AQ38: 0 | AR38: 0
A39: N20 | B39: 0 | C39: 0 | D39: 0 | E39: 0 | F39: 0 | G39: 0 | H39: 0 | I39: 0 | J39: 0 | K39: 0 | L39: 0 | M39: 0 | N39: 0 | O39: 0 | P39: 0 | Q39: 0 | R39: 0 | S39: 0 | T39: 0 | U39: 0 | V39: 42857 | W39: 0 | X39: 0 | Y39: 0 | Z39: 0 | AA39: 0 | AB39: 0 | AC39: 42857 | AD39: 0 | AE39: 0 | AF39: 0 | AG39: 0 | AH39: 0 | AI39: 0 | AJ39: 0 | AK39: 0 | AL39: 0 | AM39: 0 | AN39: 0 | AO39: 0 | AP39: 0 | AQ39: 0 | AR39: 0
A40: N21 | B40: 0 | C40: 0 | D40: 0 | E40: 0 | F40: 0 | G40: 0 | H40: 0 | I40: 0 | J40: 0 | K40: 0 | L40: 0 | M40: 0 | N40: 0 | O40: 0 | P40: 0 | Q40: 0 | R40: 0 | S40: 0 | T40: 0 | V40: 0 | W40: 42857 | X40: 0 | Y40: 0 | Z40: 0 | AA40: 0 | AB40: 0 | AC40: 0 | AD40: 0 | AE40: 0 | AF40: 0 | AG40: 0 | AH40: 0 | AI40: 0 | AJ40: 0 | AK40: 0 | AL40: 0 | AM40: 0 | AN40: 0 | AO40: 0 | AP40: 0 | AQ40: 0 | AR40: 0
A41: N22 | B41: 0 | C41: 0 | D41: 0 | E41: 0 | F41: 0 | G41: 0 | H41: 0 | I41: 0 | J41: 0 | K41: 0 | L41: 0 | M41: 0 | N41: 0 | O41: 0 | P41: 0 | Q41: 0 | R41: 0 | S41: 0 | U41: 0 | W41: 0 | X41: 42857 | Y41: 0 | Z41: 0 | AA41: 0 | AB41: 0 | AC41: 0 | AD41: 0 | AE41: 0 | AF41: 0 | AG41: 0 | AH41: 0 | AI41: 0 | AJ41: 0 | AK41: 0 | AL41: 0 | AM41: 0 | AN41: 0 | AO41: 0 | AP41: 0 | AQ41: 0 | AR41: 0
A42: N23 | B42: 0 | C42: 0 | D42: 0 | E42: 0 | F42: 0 | G42: 0 | H42: 0 | I42: 0 | J42: 0 | K42: 0 | L42: 0 | M42: 0 | N42: 0 | O42: 0 | P42: 0 | Q42: 0 | R42: 0 | S42: 0 | T42: 0 | U42: 0 | V42: 0 | X42: 0 | Y42: 42857 | Z42: 0 | AA42: 0 | AB42: 0 | AC42: 0 | AD42: 0 | AE42: 0 | AF42: 0 | AG42: 0 | AH42: 0 | AI42: 0 | AJ42: 0 | AK42: 0 | AL42: 0 | AM42: 0 | AN42: 0 | AO42: 0 | AP42: 0 | AQ42: 0 | AR42: 0
A43: N24 | B43: 0 | C43: 0 | D43: 0 | E43: 0 | F43: 0 | G43: 0 | H43: 0 | I43: 0 | J43: 0 | K43: 0 | L43: 0 | M43: 0 | N43: 0 | O43: 0 | P43: 0 | Q43: 0 | R43: 0 | S43: 0 | T43: 0 | U43: 0 | V43: 0 | W43: 0 | Y43: 0 | Z43: 42857 | AA43: 0 | AB43: 0 | AC43: 0 | AD43: 0 | AE43: 0 | AF43: 0 | AG43: 0 | AH43: 0 | AI43: 0 | AJ43: 0 | AK43: 0 | AL43: 0 | AM43: 0 | AN43: 0 | AO43: 0 | AP43: 0 | AQ43: 0 | AR43: 0
A44: N25 | B44: 0 | C44: 0 | D44: 0 | E44: 0 | F44: 0 | G44: 0 | H44: 0 | I44: 0 | J44: 0 | K44: 0 | L44: 0 | M44: 0 | N44: 0 | O44: 0 | P44: 0 | Q44: 0 | R44: 0 | S44: 0 | T44: 0 | U44: 0 | V44: 0 | W44: 0 | X44: 0 | Z44: 0 | AA44: 42857 | AB44: 0 | AC44: 0 | AD44: 0 | AE44: 0 | AF44: 0 | AG44: 0 | AH44: 0 | AI44: 0 | AJ44: 0 | AK44: 0 | AL44: 0 | AM44: 0 | AN44: 0 | AO44: 0 | AP44: 0 | AQ44: 0 | AR44: 0
A45: N26 | B45: 0 | C45: 0 | D45: 0 | E45: 0 | F45: 0 | G45: 0 | H45: 0 | I45: 0 | J45: 0 | K45: 0 | L45: 0 | M45: 0 | N45: 0 | O45: 0 | P45: 0 | Q45: 0 | R45: 0 | S45: 0 | T45: 0 | U45: 0 | V45: 0 | W45: 0 | X45: 0 | Y45: 0 | AA45: 0 | AB45: 42857 | AC45: 0 | AD45: 0 | AE45: 0 | AF45: 0 | AG45: 0 | AH45: 0 | AI45: 0 | AJ45: 0 | AK45: 0 | AL45: 0 | AM45: 0 | AN45: 0 | AO45: 0 | AP45: 0 | AQ45: 0 | AR45: 0
...

Sheet InitialPipelineDiameters
A1: Table of Initial Pipeline Diameters between Sites [inch]
A2: NODES | B2: N01 | C2: N02 | D2: N03 | E2: N04 | F2: N05 | G2: N06 | H2: N07 | I2: N08 | J2: N09 | K2: N10 | L2: N11 | M2: N12 | N2: N13 | O2: N14 | P2: N15 | Q2: N16 | R2: N17 | S2: N18 | T2: N19 | U2: N20 | V2: N21 | W2: N22 | X2: N23 | Y2: N24 | Z2: N25 | AA2: N26 | AB2: N27 | AC2: N28 | AD2: K01 | AE2: K02 | AF2: K03 | AG2: K04 | AH2: K05 | AI2: R02 | AJ2: R03 | AK2: R04 | AL2: R05 | AM2: S02 | AN2: S04 | AO2: S05 | AP2: CP01 | AQ2: CP02 | AR2: CP03
A3: PP01 | B3: 6 | C3: 0 | D3: 0 | E3: 0 | F3: 0 | G3: 0 | H3: 0 | I3: 0 | J3: 0 | K3: 0 | L3: 0 | M3: 0 | N3: 0 | O3: 0 | P3: 0 | Q3: 0 | R3: 0 | S3: 0 | T3: 0 | U3: 0 | V3: 0 | W3: 0 | X3: 0 | Y3: 0 | Z3: 0 | AA3: 0 | AB3: 0 | AC3: 0 | AD3: 0 | AE3: 0 | AF3: 0 | AG3: 0 | AH3: 0 | AI3: 0 | AJ3: 0 | AK3: 0 | AL3: 0 | AM3: 0 | AN3: 0 | AO3: 0 | AP3: 0 | AQ3: 0 | AR3: 0
A4: PP02 | B4: 0 | C4: 0 | D4: 0 | E4: 0 | F4: 6 | G4: 0 | H4: 0 | I4: 0 | J4: 0 | K4: 0 | L4: 0 | M4: 0 | N4: 0 | O4: 0 | P4: 0 | Q4: 0 | R4: 0 | S4: 0 | T4: 0 | U4: 0 | V4: 0 | W4: 0 | X4: 0 | Y4: 0 | Z4: 0 | AA4: 0 | AB4: 0 | AC4: 0 | AD4: 0 | AE4: 0 | AF4: 0 | AG4: 0 | AH4: 0 | AI4: 0 | AJ4: 0 | AK4: 0 | AL4: 0 | AM4: 0 | AN4: 0 | AO4: 0 | AP4: 0 | AQ4: 0 | AR4: 0
A5: PP03 | B5: 0 | C5: 0 | D5: 0 | E5: 0 | F5: 0 | G5: 6 | H5: 0 | I5: 0 | J5: 0 | K5: 0 | L5: 0 | M5: 0 | N5: 0 | O5: 0 | P5: 0 | Q5: 0 | R5: 0 | S5: 0 | T5: 0 | U5: 0 | V5: 0 | W5: 0 | X5: 0 | Y5: 0 | Z5: 0 | AA5: 0 | AB5: 0 | AC5: 0 | AD5: 0 | AE5: 0 | AF5: 0 | AG5: 0 | AH5: 0 | AI5: 0 | AJ5: 0 | AK5: 0 | AL5: 0 | AM5: 0 | AN5: 0 | AO5: 0 | AP5: 0 | AQ5: 0 | AR5: 0
A6: PP04 | B6: 0 | C6: 0 | D6: 0 | E6: 0 | F6: 0 | G6: 0 | H6: 0 | I6: 0 | J6: 0 | K6: 0 | L6: 6 | M6: 0 | N6: 0 | O6: 0 | P6: 0 | Q6: 0 | R6: 0 | S6: 0 | T6: 0 | U6: 0 | V6: 0 | W6: 0 | X6: 0 | Y6: 0 | Z6: 0 | AA6: 0 | AB6: 0 | AC6: 0 | AD6: 0 | AE6: 0 | AF6: 0 | AG6: 0 | AH6: 0 | AI6: 0 | AJ6: 0 | AK6: 0 | AL6: 0 | AM6: 0 | AN6: 0 | AO6: 0 | AP6: 0 | AQ6: 0 | AR6: 0
A7: PP05 | B7: 0 | C7: 0 | D7: 0 | E7: 0 | F7: 0 | G7: 0 | H7: 0 | I7: 0 | J7: 0 | K7: 0 | L7: 0 | M7: 0 | N7: 0 | O7: 0 | P7: 0 | Q7: 0 | R7: 0 | S7: 0 | T7: 0 | U7: 0 | V7: 0 | W7: 0 | X7: 0 | Y7: 0 | Z7: 0 | AA7: 0 | AB7: 0 | AC7: 0 | AD7: 0 | AE7: 0 | AF7: 0 | AG7: 0 | AH7: 0 | AI7: 0 | AJ7: 0 | AK7: 0 | AL7: 0 | AM7: 0 | AN7: 0 | AO7: 0 | AP7: 0 | AQ7: 0 | AR7: 0
A8: PP06 | B8: 0 | C8: 0 | D8: 0 | E8: 0 | F8: 0 | G8: 0 | H8: 0 | I8: 0 | J8: 0 | K8: 0 | L8: 0 | M8: 0 | N8: 0 | O8: 0 | P8: 0 | Q8: 6 | R8: 0 | S8: 0 | T8: 0 | U8: 0 | V8: 0 | W8: 0 | X8: 0 | Y8: 0 | Z8: 0 | AA8: 0 | AB8: 0 | AC8: 0 | AD8: 0 | AE8: 0 | AF8: 0 | AG8: 0 | AH8: 0 | AI8: 0 | AJ8: 0 | AK8: 0 | AL8: 0 | AM8: 0 | AN8: 0 | AO8: 0 | AP8: 0 | AQ8: 0 | AR8: 0
A9: PP07 | B9: 0 | C9: 0 | D9: 0 | E9: 0 | F9: 0 | G9: 0 | H9: 0 | I9: 0 | J9: 0 | K9: 0 | L9: 0 | M9: 0 | N9: 0 | O9: 0 | P9: 6 | Q9: 0 | R9: 0 | S9: 0 | T9: 0 | U9: 0 | V9: 0 | W9: 0 | X9: 0 | Y9: 0 | Z9: 0 | AA9: 0 | AB9: 0 | AC9: 0 | AD9: 0 | AE9: 0 | AF9: 0 | AG9: 0 | AH9: 0 | AI9: 0 | AJ9: 0 | AK9: 0 | AL9: 0 | AM9: 0 | AN9: 0 | AO9: 0 | AP9: 0 | AQ9: 0 | AR9: 0
A10: PP08 | B10: 0 | C10: 0 | D10: 0 | E10: 0 | F10: 0 | G10: 0 | H10: 0 | I10: 0 | J10: 0 | K10: 0 | L10: 0 | M10: 0 | N10: 0 | O10: 0 | P10: 0 | Q10: 0 | R10: 0 | S10: 6 | T10: 0 | U10: 0 | V10: 0 | W10: 0 | X10: 0 | Y10: 0 | Z10: 0 | AA10: 0 | AB10: 0 | AC10: 0 | AD10: 0 | AE10: 0 | AF10: 0 | AG10: 0 | AH10: 0 | AI10: 0 | AJ10: 0 | AK10: 0 | AL10: 0 | AM10: 0 | AN10: 0 | AO10: 0 | AP10: 0 | AQ10: 0 | AR10: 0
A11: PP09 | B11: 0 | C11: 0 | D11: 0 | E11: 0 | F11: 0 | G11: 0 | H11: 0 | I11: 0 | J11: 0 | K11: 0 | L11: 0 | M11: 0 | N11: 0 | O11: 0 | P11: 0 | Q11: 0 | R11: 0 | S11: 0 | T11: 0 | U11: 0 | V11: 6 | W11: 0 | X11: 0 | Y11: 0 | Z11: 0 | AA11: 0 | AB11: 0 | AC11: 0 | AD11: 0 | AE11: 0 | AF11: 0 | AG11: 0 | AH11: 0 | AI11: 0 | AJ11: 0 | AK11: 0 | AL11: 0 | AM11: 0 | AN11: 0 | AO11: 0 | AP11: 0 | AQ11: 0 | AR11: 0
A12: PP10 | B12: 0 | C12: 0 | D12: 0 | E12: 0 | F12: 0 | G12: 0 | H12: 0 | I12: 0 | J12: 0 | K12: 0 | L12: 0 | M12: 0 | N12: 0 | O12: 0 | P12: 0 | Q12: 0 | R12: 0 | S12: 0 | T12: 6 | U12: 0 | V12: 0 | W12: 0 | X12: 0 | Y12: 0 | Z12: 0 | AA12: 0 | AB12: 0 | AC12: 0 | AD12: 0 | AE12: 0 | AF12: 0 | AG12: 0 | AH12: 0 | AI12: 0 | AJ12: 0 | AK12: 0 | AL12: 0 | AM12: 0 | AN12: 0 | AO12: 0 | AP12: 0 | AQ12: 0 | AR12: 0
